Workbook
Name СИКН_№301: Январь!$C$6:$C$36
Name СИКН_№304: Январь!$D$6:$D$36
Name СИКН_№307: Январь!$E$6:$E$36
Name СИКН_№310: Январь!$F$6:$F$36
Name СИКН_№312: Январь!$G$6:$G$36
Name СИКН_№315: Январь!$H$6:$H$36
Name СИКН_№318: Январь!$I$6:$I$36
Name ПСП_Восточный: Январь!$J$6:$J$36
Name СИКН_№320: Январь!$K$6:$K$36
Name СИКН_№322: Январь!$L$6:$L$36
Name СИКН_№325: Январь!$M$6:$M$36
Name СИКН_№327: Январь!$N$6:$N$36
Name СИКН_№330: Январь!$O$6:$O$36
Name СИКН_№333: Январь!$P$6:$P$36
Name СИКН_№336: Январь!$Q$6:$Q$36
Name СИКН_№339: Январь!$R$6:$R$36
Name СИКН_№341: Январь!$S$6:$S$36
Name СИКН_№344: Январь!$T$6:$T$36
Name УПСВ_1_Лесная: Январь!$U$6:$U$36
Name УПСВ_2_Озерная: Январь!$V$6:$V$36

Sheet Январь
B4: Дата | C4: Нефть тип А | F4: Нефть тип Б | I4: Нефть тип Б | J4: Нефть тип Б | K4: Нефть тип А | S4: Нефть тип Б | U4: Узлы подготовки
C5: СИКН №301 | D5: СИКН №304 | E5: СИКН №307 | F5: СИКН №310 | G5: СИКН №312 | H5: СИКН №315 | I5: СИКН №318 | J5: ПСП Восточный | K5: СИКН №320 | L5: СИКН №322 | M5: СИКН №325 | N5: СИКН №327 | O5: СИКН №330 | P5: СИКН №333 | Q5: СИКН №336 | R5: СИКН №339 | S5: СИКН №341 | T5: СИКН №344 | U5: УПСВ-1 Лесная | V5: УПСВ-2 Озерная
B6: 46023 | C6: 0.7 | D6: 0.4 | E6: 0.76 | F6: 1 | G6: 0.5 | H6: 0.8 | I6: 0.89 | J6: 0.5 | K6: 0.4 | L6: 0.4 | M6: 0.8 | N6: 0.8 | O6: 0.95 | P6: 0.6 | Q6: 0.41 | R6: 0.2 | S6: 0.9 | T6: 0.6 | U6: 0.7 | V6: 0.2
B7: 46024 | C7: 0.7 | D7: 0.4 | E7: 0.7 | F7: 0.9 | G7: 0.51 | H7: 0.8 | I7: 1 | J7: 1.7 | K7: 0.26 | L7: 0.3 | M7: 0.8 | N7: 0.8 | O7: 0.98 | P7: 0.7 | Q7: 0.5 | R7: 0.3 | S7: 0.89 | T7: 0.6 | U7: 0.67 | V7: 0.2
B8: 46025 | C8: 0.64 | D8: 0.5 | E8: 0.8 | F8: 1 | G8: 0.4 | H8: 0.9 | I8: 0.89 | J8: 0.4 | K8: 0.3 | L8: 0.3 | M8: 0.88 | N8: 0.85 | O8: 1 | P8: 0.7 | Q8: 0.5 | R8: 0.3 | S8: 0.86 | U8: 0.7 | V8: 0.1
B9: 46026 | C9: 0.5 | D9: 0.6 | E9: 0.8 | F9: 0.9 | G9: 0.46 | H9: 0.9 | I9: 0.8 | J9: 0.4 | K9: 0.4 | L9: 0.2 | M9: 0.78 | N9: 0.85 | O9: 1 | P9: 0.8 | Q9: 0.51 | R9: 0.4 | S9: 1.1 | T9: 0.53 | U9: 0.74 | V9: 0.2
B10: 46027 | C10: 0.6 | D10: 0.5 | E10: 0.77 | F10: 1 | G10: 0.5 | H10: 0.8 | I10: 0.8 | J10: 0.44 | K10: 0.5 | L10: 0.32 | M10: 0.6 | N10: 0.7 | O10: 1.1 | P10: 0.79 | Q10: 0.5 | R10: 0.39 | S10: 1.01 | T10: 0.5 | U10: 0.7 | V10: 0.2
B11: 46028 | C11: 0.66 | D11: 0.4 | E11: 0.9 | F11: 1.06 | G11: 0.5 | H11: 0.8 | I11: 0.9 | J11: 0.5 | K11: 0.42 | L11: 0.3 | M11: 0.6 | N11: 0.6 | O11: 1 | P11: 0.8 | Q11: 0.5 | R11: 0.4 | S11: 1.1 | T11: 0.6 | U11: 0.8 | V11: 0.2
B12: 46029 | C12: 0.7 | D12: 0.4 | E12: 0.78 | F12: 1.1 | G12: 0.5 | H12: 0.8 | I12: 0.9 | J12: 0.5 | K12: 0.5 | L12: 0.3 | M12: 0.7 | N12: 0.73 | O12: 1 | P12: 0.9 | Q12: 0.52 | R12: 0.42 | S12: 1 | T12: 0.5 | U12: 0.7 | V12: 0.32
B13: 46030 | C13: 0.8 | D13: 0.5 | E13: 0.8 | F13: 1.1 | G13: 0.5 | H13: 0.8 | I13: 1 | J13: 0.5 | K13: 0.5 | L13: 0.2 | M13: 0.7 | N13: 0.83 | O13: 0.9 | P13: 0.8 | Q13: 0.5 | R13: 0.4 | S13: 0.81 | T13: 0.5 | U13: 0.73 | V13: 0.31
B14: 46031 | C14: 0.63 | D14: 0.4 | E14: 0.9 | F14: 1 | G14: 0.4 | H14: 0.71 | I14: 0.9 | J14: 0.5 | K14: 0.4 | L14: 0.2 | M14: 0.7 | N14: 0.8 | O14: 0.87 | P14: 0.82 | Q14: 0.4 | R14: 0.3 | S14: 0.78 | T14: 0.54 | U14: 0.7 | V14: 0.36
B15: 46032 | C15: 0.6 | D15: 0.5 | E15: 0.9 | F15: 0.9 | G15: 0.5 | H15: 0.8 | I15: 0.8 | L15: 0.2 | M15: 0.7 | N15: 0.7 | O15: 0.91 | P15: 0.8 | Q15: 0.53 | S15: 0.9 | T15: 0.69 | U15: 0.7 | V15: 0.3
B16: 46033 | C16: 0.6 | D16: 0.5 | E16: 0.8 | F16: 1.1 | G16: 0.4 | H16: 0.91 | I16: 0.93 | J16: 0.4 | K16: 0.2 | L16: 0.2 | M16: 0.7 | N16: 0.7 | O16: 0.9 | P16: 0.7 | Q16: 0.5 | R16: 0.2 | S16: 1 | T16: 0.6 | U16: 0.7 | V16: 0.25
B17: 46034 | C17: 0.6 | D17: 0.4 | E17: 0.9 | F17: 1.2 | G17: 0.5 | H17: 0.7 | I17: 1 | J17: 0.43 | K17: 0.3 | L17: 0.3 | M17: 0.7 | N17: 0.7 | O17: 0.9 | P17: 0.7 | Q17: 0.5 | R17: 0.3 | S17: 1.1 | T17: 0.5 | U17: 0.7 | V17: 0.2
B18: 46035 | C18: 0.6 | D18: 0.3 | E18: 0.85 | F18: 1.1 | G18: 0.5 | H18: 0.7 | I18: 0.99 | J18: 0.44 | K18: 0.25 | L18: 0.3 | M18: 0.7 | N18: 0.8 | O18: 0.9 | P18: 0.6 | R18: 0.1 | S18: 1.07 | T18: 0.59 | U18: 0.8 | V18: 0.3
B19: 46036 | C19: 0.7 | D19: 0.39 | E19: 0.83 | F19: 1.1 | G19: 0.5 | I19: 0.97 | J19: 0.4 | K19: 0.4 | L19: 0.4 | M19: 0.7 | N19: 0.71 | O19: 1 | P19: 0.6 | Q19: 0.6 | R19: 0.2 | S19: 1 | T19: 0.6 | U19: 0.7 | V19: 0.3
B20: 46037 | C20: 0.6 | D20: 0.4 | E20: 0.8 | F20: 1 | G20: 0.4 | H20: 0.83 | I20: 1 | J20: 0.48 | K20: 0.49 | L20: 0.4 | M20: 0.81 | N20: 0.6 | O20: 0.87 | P20: 0.7 | Q20: 0.5 | R20: 0.2 | S20: 1 | T20: 0.6 | U20: 0.7 | V20: 0.2
B21: 46038 | C21: 0.5 | D21: 0.4 | E21: 0.7 | F21: 1.1 | G21: 0.6 | H21: 0.96 | I21: 1 | J21: 0.5 | K21: 0.5 | L21: 0.4 | M21: 0.8 | N21: 0.7 | O21: 0.8 | P21: 0.73 | Q21: 0.5 | R21: 0.3 | S21: 1 | T21: 0.56 | U21: 0.6 | V21: 0.1
B22: 46039 | C22: 0.7 | D22: 0.3 | E22: 0.7 | F22: 1.2 | G22: 0.5 | H22: 0.98 | I22: 0.93 | K22: 0.45 | L22: 0.46 | M22: 0.8 | N22: 0.71 | O22: 0.75 | P22: 0.7 | Q22: 0.5 | R22: 0.3 | S22: 1 | T22: 0.5 | U22: 0.5 | V22: 0.3
B23: 46040 | C23: 0.7 | D23: 0.5 | E23: 0.8 | F23: 1.1 | G23: 0.4 | H23: 0.9 | I23: 0.9 | J23: 0.5 | K23: 0.5 | L23: 0.4 | M23: 0.8 | N23: 0.8 | O23: 0.82 | P23: 0.8 | Q23: 0.3 | R23: 0.2 | S23: 0.9 | T23: 0.4 | U23: 0.65 | V23: 0.2
B24: 46041 | C24: 0.6 | D24: 0.64 | E24: 0.8 | F24: 1 | G24: 0.3 | H24: 0.9 | I24: 0.9 | J24: 0.42 | K24: 0.5 | L24: 0.3 | M24: 0.7 | N24: 0.8 | O24: 0.9 | P24: 0.7 | Q24: 0.4 | R24: 0.3 | S24: 1 | T24: 0.4 | U24: 0.7 | V24: 0.2
B25: 46042 | C25: 0.5 | D25: 0.6 | E25: 0.9 | F25: 1 | G25: 0.47 | H25: 0.8 | I25: 1.06 | J25: 0.4 | K25: 0.3 | L25: 0.3 | M25: 0.83 | N25: 0.8 | O25: 1 | P25: 0.6 | Q25: 0.5 | R25: 0.1 | S25: 1 | T25: 0.5 | U25: 0.7 | V25: 0.3
B26: 46043 | C26: 0.6 | D26: 0.4 | E26: 0.76 | F26: 1 | G26: 0.4 | H26: 0.9 | I26: 0.9 | J26: 0.37 | K26: 0.3 | L26: 0.24 | M26: 0.78 | N26: 0.9 | O26: 1 | P26: 0.67 | Q26: 0.53 | R26: 0.1 | S26: 1 | T26: 0.4 | U26: 0.8 | V26: 0.3
B27: 46044 | C27: 0.66 | D27: 0.4 | E27: 0.8 | F27: 0.9 | G27: 0.4 | H27: 0.9 | I27: 0.8 | J27: 0.3 | K27: 0.41 | L27: 0.3 | M27: 0.6 | N27: 0.91 | O27: 0.9 | P27: 0.7 | Q27: 0.5 | R27: 0.2 | S27: 1 | T27: 0.5 | U27: 0.6 | V27: 0.3
B28: 46045 | C28: 0.7 | D28: 0.3 | E28: 0.8 | F28: 0.9 | G28: 0.2 | H28: 1.01 | I28: 0.8 | J28: 0.53 | K28: 0.4 | L28: 0.4 | M28: 0.6 | N28: 0.8 | O28: 0.9 | P28: 0.72 | Q28: 0.4 | R28: 0.2 | S28: 0.9 | T28: 0.54 | U28: 0.58 | V28: 0.3
B29: 46046 | C29: 0.7 | D29: 0.4 | E29: 0.8 | F29: 0.9 | G29: 0.3 | H29: 1 | I29: 0.9 | J29: 0.5 | K29: 0.4 | L29: 0.23 | M29: 0.7 | N29: 0.7 | O29: 0.9 | P29: 0.7 | Q29: 0.5 | R29: 0.1 | S29: 1 | T29: 0.6 | U29: 0.6 | V29: 0.3
B30: 46047 | C30: 0.6 | D30: 0.4 | E30: 0.9 | F30: 1 | G30: 0.3 | H30: 0.9 | I30: 0.9 | J30: 0.4 | K30: 0.48 | L30: 0.3 | N30: 0.6 | O30: 0.8 | P30: 0.6 | Q30: 0.47 | R30: 0.3 | S30: 1 | T30: 0.6 | U30: 0.62 | V30: 0.3
B31: 46048 | C31: 0.7 | D31: 0.3 | E31: 0.89 | F31: 0.94 | G31: 0.4 | H31: 0.95 | I31: 0.9 | J31: 0.32 | K31: 0.5 | L31: 0.2 | M31: 0.6 | N31: 0.7 | O31: 0.7 | P31: 0.69 | Q31: 0.4 | R31: 0.4 | S31: 0.9 | T31: 0.6 | U31: 0.49 | V31: 0.2
B32: 46049 | C32: 0.8 | D32: 0.3 | E32: 0.9 | F32: 0.99 | G32: 0.4 | H32: 0.9 | I32: 0.9 | J32: 0.3 | K32: 0.5 | L32: 0.5 | M32: 0.6 | O32: 0.7 | P32: 0.7 | Q32: 0.47 | R32: 0.3 | S32: 1 | T32: 0.56 | U32: 0.62 | V32: 0.2
B33: 46050 | C33: 0.7 | D33: 0.3 | E33: 0.8 | F33: 1 | G33: 0.4 | H33: 0.8 | I33: 0.97 | J33: 0.3 | K33: 0.4 | L33: 0.4 | M33: 0.77 | N33: 0.7 | O33: 0.7 | P33: 0.6 | Q33: 0.5 | R33: 0.36 | S33: 1 | T33: 0.5 | U33: 0.5 | V33: 0.4
B34: 46051 | C34: 0.7 | D34: 0.4 | E34: 0.7 | F34: 1 | G34: 0.4 | H34: 0.8 | I34: 1 | J34: 0.3 | K34: 0.41 | L34: 0.47 | M34: 0.7 | N34: 0.77 | O34: 0.7 | Q34: 0.5 | R34: 0.4 | S34: 1 | U34: 0.5 | V34: 0.3
B35: 46052 | C35: 0.6 | D35: 0.34 | E35: 0.75 | F35: 1.1 | G35: 0.5 | H35: 0.81 | I35: 1 | J35: 0.4 | K35: 0.34 | L35: 0.5 | M35: 0.6 | N35: 0.77 | O35: 0.8 | P35: 0.8 | Q35: 0.4 | R35: 0.4 | S35: 1 | T35: 0.5 | U35: 0.6 | V35: 0.3
B36: 46053 | C36: 0.6 | D36: 0.4 | E36: 0.8 | F36: 1.2 | G36: 0.7 | H36: 0.9 | I36: 0.9 | K36: 0.3 | L36: 0.4 | M36: 0.6 | N36: 0.8 | O36: 0.9 | P36: 0.8 | Q36: 0.5 | R36: 0.4 | S36: 1.09 | T36: 0.5 | U36: 0.5 | V36: 0.4

Sheet Февраль
B4: Дата | C4: Нефть тип А | F4: Нефть тип Б | I4: Нефть тип Б | J4: Нефть тип Б | K4: Нефть тип А | S4: Нефть тип Б | U4: Узлы подготовки
C5: СИКН №301 | D5: СИКН №304 | E5: СИКН №307 | F5: СИКН №310 | G5: СИКН №312 | H5: СИКН №315 | I5: СИКН №318 | J5: ПСП Восточный | K5: СИКН №320 | L5: СИКН №322 | M5: СИКН №325 | N5: СИКН №327 | O5: СИКН №330 | P5: СИКН №333 | Q5: СИКН №336 | R5: СИКН №339 | S5: СИКН №341 | T5: СИКН №344 | U5: УПСВ-1 Лесная | V5: УПСВ-2 Озерная
B6: 46054 | C6: 0.6 | D6: 0.4 | E6: 0.8 | F6: 1.04 | G6: 0.7 | H6: 1 | I6: 0.88 | J6: 0.5 | K6: 0.47 | L6: 0.3 | M6: 0.64 | N6: 0.75 | O6: 0.8 | P6: 0.7 | Q6: 0.4 | R6: 0.4 | S6: 1.02 | T6: 0.6 | U6: 0.7 | V6: 0.42
B7: 46055 | C7: 0.61 | D7: 0.5 | E7: 0.9 | F7: 1.1 | G7: 0.4 | H7: 1 | I7: 0.95 | J7: 0.42 | K7: 0.41 | L7: 0.4 | M7: 0.7 | N7: 0.82 | O7: 0.77 | P7: 0.8 | Q7: 0.38 | R7: 0.4 | S7: 0.94 | T7: 0.6 | U7: 0.7 | V7: 0.4
B8: 46056 | D8: 0.5 | E8: 0.8 | F8: 1.1 | G8: 0.4 | H8: 0.8 | I8: 0.8 | J8: 0.4 | K8: 0.3 | L8: 0.3 | M8: 0.7 | N8: 0.8 | O8: 0.8 | P8: 0.7 | Q8: 0.4 | R8: 0.3 | S8: 1.1 | T8: 0.6 | U8: 0.6 | V8: 0.32
B9: 46057 | C9: 0.6 | D9: 0.6 | E9: 0.78 | F9: 0.97 | G9: 0.5 | H9: 0.8 | I9: 0.8 | J9: 0.4 | K9: 0.32 | L9: 0.32 | M9: 0.7 | N9: 0.7 | O9: 0.8 | P9: 0.7 | Q9: 0.33 | R9: 0.4 | S9: 1.04 | T9: 0.6 | U9: 0.7 | V9: 0.2
B10: 46058 | C10: 0.7 | D10: 0.49 | E10: 0.8 | F10: 1 | G10: 0.4 | H10: 0.9 | I10: 0.85 | J10: 0.4 | K10: 0.4 | L10: 0.41 | M10: 0.6 | N10: 0.8 | O10: 0.9 | P10: 0.64 | Q10: 0.4 | R10: 0.34 | S10: 1 | T10: 0.7 | U10: 0.7 | V10: 0.2
B11: 46059 | C11: 0.6 | D11: 0.49 | E11: 0.9 | F11: 0.9 | G11: 0.4 | H11: 0.79 | I11: 0.9 | J11: 0.49 | K11: 0.4 | L11: 0.4 | M11: 0.73 | N11: 0.7 | O11: 0.81 | P11: 0.74 | Q11: 0.4 | R11: 0.2 | S11: 1 | T11: 0.7 | U11: 0.5 | V11: 0.2
B12: 46060 | C12: 0.7 | D12: 0.51 | E12: 0.8 | F12: 1 | G12: 0.4 | H12: 0.8 | J12: 0.5 | K12: 0.4 | L12: 0.4 | M12: 0.8 | N12: 0.69 | O12: 0.9 | P12: 0.8 | Q12: 0.6 | R12: 0.3 | S12: 1.1 | T12: 0.65 | U12: 0.6 | V12: 0.2
B13: 46061 | C13: 0.7 | D13: 0.4 | E13: 0.9 | F13: 0.9 | G13: 0.35 | H13: 0.9 | I13: 0.9 | J13: 0.6 | K13: 0.3 | L13: 0.4 | M13: 0.82 | N13: 0.71 | O13: 0.9 | P13: 0.8 | Q13: 0.4 | R13: 0.3 | S13: 1.01 | T13: 0.7 | U13: 0.7 | V13: 0.2
B14: 46062 | C14: 0.7 | D14: 0.4 | E14: 0.9 | F14: 0.88 | G14: 0.5 | H14: 0.99 | I14: 0.9 | J14: 0.4 | K14: 0.32 | L14: 0.45 | M14: 0.7 | N14: 0.8 | O14: 1 | P14: 0.8 | Q14: 0.4 | R14: 0.26 | T14: 0.64 | U14: 0.7 | V14: 0.3
B15: 46063 | C15: 0.7 | D15: 0.4 | E15: 0.8 | F15: 0.9 | G15: н/д | H15: 1 | I15: 0.84 | J15: 0.34 | K15: 0.4 | L15: 0.4 | M15: 0.8 | N15: 0.7 | O15: 1 | P15: 0.7 | Q15: 0.5 | R15: 0.3 | S15: 1.1 | T15: 0.6 | U15: 0.64 | V15: 0.1
B16: 46064 | C16: 0.8 | D16: 0.4 | E16: 0.8 | F16: 1 | G16: 0.4 | H16: 0.9 | I16: 0.8 | J16: 0.4 | K16: 0.42 | L16: 0.33 | M16: 0.7 | N16: 0.7 | O16: 0.9 | P16: 0.8 | Q16: 0.45 | R16: 0.31 | S16: 1.1 | T16: 0.6 | U16: 0.62 | V16: 0.2
B17: 46065 | C17: 0.8 | D17: 0.5 | E17: 0.8 | F17: 1 | G17: 0.4 | H17: 0.9 | I17: 0.97 | J17: 0.4 | K17: 0.5 | L17: 0.3 | N17: 0.8 | O17: 0.9 | P17: 0.7 | Q17: 0.5 | R17: 0.3 | S17: 1.1 | T17: 0.4 | U17: 0.7 | V17: 0.3
B18: 46066 | C18: 0.97 | D18: 0.4 | E18: 0.86 | F18: 1.1 | G18: 0.4 | H18: 0.9 | I18: 1 | J18: 0.5 | K18: 0.4 | L18: 0.29 | M18: 0.7 | N18: 0.9 | O18: 0.9 | P18: 0.7 | Q18: 0.4 | R18: 0.32 | S18: 1 | T18: 0.4 | U18: 0.61 | V18: 0.3
B19: 46067 | C19: 0.9 | D19: 0.4 | E19: 0.7 | F19: 1 | G19: 0.3 | H19: 0.94 | I19: 0.8 | J19: 0.4 | K19: 0.5 | L19: 0.22 | M19: 0.8 | N19: 0.8 | O19: 1 | P19: 0.8 | Q19: 0.4 | R19: 0.39 | S19: 1.1 | T19: 0.5 | U19: 0.6 | V19: 0.2
B20: 46068 | C20: 0.8 | D20: 0.4 | E20: 0.7 | F20: 1.1 | G20: 0.4 | H20: 0.8 | I20: 0.8 | J20: 0.4 | K20: 0.4 | L20: 0.3 | M20: 0.8 | N20: 0.8 | P20: 0.7 | Q20: 0.4 | R20: 0.4 | S20: 1 | U20: 0.61 | V20: 0.2
B21: 46069 | C21: 0.7 | D21: 0.47 | E21: 0.8 | F21: 1 | G21: 0.3 | H21: 0.8 | I21: 0.79 | J21: 0.4 | K21: 0.3 | L21: 0.3 | M21: 0.7 | N21: 0.9 | O21: 0.9 | P21: 0.7 | Q21: 0.4 | R21: 0.4 | S21: 1 | T21: 0.7 | U21: 0.7 | V21: 0.2
B22: 46070 | C22: 0.7 | D22: 0.4 | E22: 0.72 | F22: 1 | G22: 0.4 | H22: 1 | I22: 0.9 | J22: 0.4 | K22: 0.4 | L22: 0.3 | M22: 0.6 | N22: 0.9 | O22: 0.8 | P22: 0.7 | Q22: 0.5 | R22: 0.5 | S22: 1.1 | T22: 0.62 | U22: 0.7 | V22: 0.19
B23: 46071 | C23: 0.5 | D23: 0.4 | E23: 0.8 | F23: 1.2 | G23: 0.43 | H23: 0.99 | I23: 0.98 | J23: 0.5 | K23: 0.4 | L23: 0.4 | M23: 0.7 | N23: 0.9 | O23: 0.8 | P23: 0.7 | Q23: 0.6 | R23: 0.46 | S23: 1 | T23: 0.6 | U23: 0.7 | V23: 0.2
B24: 46072 | C24: 0.55 | D24: 0.5 | E24: 0.9 | F24: 1.1 | G24: 0.4 | H24: 0.8 | I24: 0.8 | J24: 0.4 | K24: 0.5 | L24: 0.3 | M24: 0.6 | N24: 0.8 | O24: 0.95 | Q24: 0.5 | R24: 0.5 | S24: 0.9 | T24: 0.6 | U24: 0.66 | V24: 0.3
B25: 46073 | C25: 0.6 | D25: 0.5 | E25: 0.9 | F25: 1 | G25: 0.5 | H25: 0.9 | I25: 0.88 | J25: 0.5 | K25: 0.5 | L25: 0.4 | M25: 0.74 | N25: 0.7 | O25: 0.96 | P25: 0.8 | Q25: 0.4 | R25: 0.5 | S25: 1.1 | T25: 0.5 | V25: 0.3
B26: 46074 | C26: 0.5 | D26: 0.5 | E26: 1 | F26: 1.1 | G26: 0.46 | H26: 0.75 | I26: 0.9 | J26: 0.6 | K26: 0.4 | L26: 0.3 | M26: 0.7 | N26: 0.8 | O26: 1 | P26: 0.8 | Q26: 0.5 | R26: 0.4 | S26: 1.04 | T26: 0.5 | U26: 0.6 | V26: 0.4
B27: 46075 | C27: 0.6 | D27: 0.5 | E27: 0.9 | F27: 1 | G27: 0.4 | H27: 0.7 | I27: 0.9 | J27: 0.5 | K27: 0.5 | L27: 0.4 | M27: 0.89 | N27: 0.8 | O27: 1 | P27: 0.7 | Q27: 0.5 | R27: 0.29 | S27: 1 | T27: 0.48 | U27: 0.7 | V27: 0.3
B28: 46076 | C28: 0.6 | D28: 0.4 | E28: 0.8 | F28: 1 | G28: 0.5 | H28: 0.6 | I28: 1 | J28: 0.5 | K28: 0.4 | L28: 0.38 | M28: 0.8 | N28: 0.74 | O28: 0.97 | P28: 0.7 | Q28: 0.5 | R28: 0.42 | S28: 1 | T28: 0.5 | U28: 0.6 | V28: 0.33
B29: 46077 | C29: 0.8 | D29: 0.3 | E29: 0.8 | F29: 0.8 | G29: 0.4 | H29: 0.8 | I29: 0.9 | J29: 0.44 | L29: 0.4 | M29: 0.8 | N29: 0.8 | O29: 1.1 | P29: 0.7 | Q29: 0.4 | R29: 0.5 | S29: 1.1 | T29: 0.5 | U29: 0.6 | V29: 0.23
B30: 46078 | C30: 0.7 | D30: 0.4 | E30: 0.7 | F30: 0.86 | G30: 0.4 | H30: 1 | I30: 0.8 | J30: 0.5 | K30: 0.4 | L30: 0.3 | M30: 0.7 | N30: 0.8 | O30: 1.02 | P30: 0.7 | Q30: 0.6 | R30: 0.4 | S30: 1.1 | T30: 0.4 | U30: 0.7 | V30: 0.3
B31: 46079 | C31: 0.7 | D31: 0.3 | E31: 0.8 | F31: 0.8 | G31: 0.4 | H31: 0.91 | I31: 0.8 | J31: 0.5 | K31: 0.5 | L31: 0.3 | M31: 0.8 | N31: 0.92 | O31: 1.03 | P31: 0.8 | Q31: 0.5 | R31: 0.4 | S31: 1 | T31: 0.52 | U31: 0.7 | V31: 0.3
B32: 46080 | C32: 0.9 | D32: 0.3 | E32: 0.8 | F32: 0.8 | G32: 0.5 | H32: 1 | I32: 0.91 | J32: 0.6 | K32: 0.5 | L32: 0.2 | M32: 0.6 | N32: 0.9 | O32: 0.84 | P32: 0.7 | Q32: 0.6 | R32: 0.4 | S32: 1 | T32: 0.5 | U32: 0.7 | V32: 0.4
B33: 46081 | C33: 0.72 | D33: 0.4 | E33: 0.8 | F33: 0.8 | H33: 0.93 | I33: 0.9 | J33: 0.5 | K33: 0.3 | L33: 0.3 | M33: 0.7 | N33: 1 | O33: 0.77 | P33: 0.8 | Q33: 0.6 | R33: 0.4 | S33: 1.1 | T33: 0.5 | U33: 0.6 | V33: 0.3

Sheet Март
B4: Дата | C4: Нефть тип А | F4: Нефть тип Б | I4: Нефть тип Б | J4: Нефть тип Б | K4: Нефть тип А | S4: Нефть тип Б | U4: Узлы подготовки
C5: СИКН №301 | D5: СИКН №304 | E5: СИКН №307 | F5: СИКН №310 | G5: СИКН №312 | H5: СИКН №315 | I5: СИКН №318 | J5: ПСП Восточный | K5: СИКН №320 | L5: СИКН №322 | M5: СИКН №325 | N5: СИКН №327 | O5: СИКН №330 | P5: СИКН №333 | Q5: СИКН №336 | R5: СИКН №339 | S5: СИКН №341 | T5: СИКН №344 | U5: УПСВ-1 Лесная | V5: УПСВ-2 Озерная
B6: 46082 | C6: 0.6 | D6: 0.44 | E6: 0.9 | F6: 0.9 | G6: 0.4 | H6: 1 | I6: 0.8 | J6: 0.6 | K6: 0.31 | L6: 0.5 | M6: 0.7 | N6: 1 | O6: 0.9 | P6: 0.76 | Q6: 0.6 | R6: 0.4 | S6: 1 | U6: 0.71 | V6: 0.3
B7: 46083 | C7: 0.5 | D7: 0.45 | E7: 0.8 | F7: 0.9 | G7: 0.39 | H7: 0.9 | I7: 0.8 | J7: 0.5 | K7: 0.39 | L7: 0.3 | M7: 0.7 | N7: 0.9 | O7: 0.9 | P7: 0.62 | Q7: 0.6 | R7: 0.4 | S7: 0.9 | T7: 0.5 | U7: 0.6 | V7: 0.4
B8: 46084 | C8: 0.56 | D8: 0.5 | E8: 0.84 | F8: 0.91 | G8: 0.5 | H8: 0.9 | I8: 0.9 | J8: 0.4 | K8: 0.4 | L8: 0.4 | M8: 0.77 | N8: 0.8 | O8: 0,45 | P8: 0.7 | Q8: 0.6 | R8: 0.3 | S8: 1.1 | T8: 0.5 | U8: 0.8 | V8: 0.4
B9: 46085 | C9: 0.6 | D9: 0.4 | E9: 0.9 | F9: 0.8 | G9: 0.5 | H9: 0.93 | I9: 0.99 | J9: 0.4 | K9: 0.3 | L9: 0.46 | M9: 0.7 | N9: 0.7 | O9: 0.96 | P9: 0.7 | Q9: 0.5 | R9: 0.2 | S9: 1.02 | T9: 0.5 | U9: 0.7 | V9: 0.5
B10: 46086 | C10: 0.6 | D10: 0.4 | E10: 0.8 | F10: 0.8 | G10: 0.46 | H10: 0.8 | I10: 1 | J10: 0.5 | K10: 0.31 | L10: 0.4 | M10: 0.7 | N10: 0.8 | O10: 0.9 | P10: 0.7 | Q10: 0.66 | R10: 0.2 | S10: 1.01 | T10: 0.3 | U10: 0.6 | V10: 0.4
B11: 46087 | C11: 0.68 | D11: 0.4 | E11: 0.7 | F11: 0.94 | G11: 0.41 | H11: 0.9 | I11: 1.03 | J11: 2.1 | K11: 0.2 | L11: 0.32 | M11: 0.7 | N11: 0.7 | O11: 0.8 | P11: 0.7 | Q11: 0.7 | R11: 0.31 | S11: 0.9 | T11: 0.5 | U11: 0.7 | V11: 0.4
B12: 46088 | C12: 0.6 | D12: 0.3 | E12: 0.8 | F12: 0.9 | G12: 0.4 | H12: 0.8 | I12: 0.9 | J12: 0.3 | L12: 0.4 | M12: 0.7 | N12: 0.7 | O12: 0.8 | P12: 0.8 | Q12: 0.6 | R12: 0.35 | S12: 0.95 | T12: 0.7 | U12: 0.7 | V12: 0.4
B13: 46089 | C13: 0.7 | D13: 0.4 | E13: 0.7 | F13: 0.9 | G13: 0.4 | H13: 0.9 | J13: 0.26 | K13: 0.4 | L13: 0.36 | M13: 0.8 | N13: 0.8 | O13: 0.8 | P13: 0.79 | Q13: 0.5 | R13: 0.2 | S13: 0.9 | T13: 0.7 | U13: 0.8 | V13: 0.4
B14: 46090 | C14: 0.67 | D14: 0.3 | E14: 0.8 | F14: 1.03 | G14: 0.5 | H14: 0.9 | I14: 1.1 | J14: 0.4 | K14: 0.3 | L14: 0.3 | M14: 0.7 | N14: 0.8 | O14: 0.85 | P14: 0.7 | Q14: 0.5 | R14: 0.3 | S14: 0.9 | T14: 0.6 | U14: 0.8 | V14: 0.28
B15: 46091 | C15: 0.68 | D15: 0.3 | E15: 0.77 | F15: 0.9 | G15: 0.5 | H15: 0.91 | I15: 1 | K15: 0.2 | L15: 0.4 | M15: 0.6 | N15: 0.9 | O15: 0.9 | P15: 0.69 | Q15: 0.5 | R15: 0.2 | S15: 0.86 | T15: 0.6 | U15: 0.7 | V15: 0.43
B16: 46092 | C16: 0.6 | D16: 0.4 | E16: 0.8 | F16: 0.9 | G16: 0.6 | H16: 0.92 | I16: 0.9 | J16: 0.4 | L16: 0.3 | M16: 0.68 | N16: 1 | O16: 1 | P16: 0.72 | Q16: 0.5 | R16: 0.4 | S16: 0.9 | T16: 0.6 | U16: 0.6 | V16: 0.4
B17: 46093 | C17: 0.6 | D17: 0.42 | E17: 0.9 | F17: 1 | G17: 0.65 | H17: 1 | I17: 0.9 | J17: 0.4 | K17: 0.24 | L17: 0.3 | M17: 0.75 | N17: 1 | O17: 0.95 | P17: 0.7 | Q17: 0.5 | R17: 0.4 | S17: 1.1 | T17: 0.6 | U17: 0.69 | V17: 0.4
B18: 46094 | C18: 0.6 | D18: 0.4 | E18: 0.8 | F18: 0.96 | G18: 0.7 | H18: 0.9 | I18: 0.8 | J18: 0.39 | K18: 0.19 | L18: 0.3 | M18: 0.7 | N18: 0.9 | O18: 0.9 | P18: 0.8 | Q18: 0.43 | R18: 0.4 | S18: 1 | T18: 0.6 | U18: 0.8
B19: 46095 | C19: 0.6 | D19: 0.4 | E19: 0.8 | F19: 1.2 | G19: 0.5 | H19: 1 | I19: 0.9 | J19: 0.4 | K19: 0.3 | L19: 0.1 | M19: 0.7 | N19: 0.8 | P19: 0.75 | Q19: 0.4 | R19: 0.5 | S19: 1 | T19: 1.8 | U19: 0.58 | V19: 0.4
B20: 46096 | C20: 0.7 | D20: 0.33 | E20: 0.9 | F20: 1 | G20: 0.5 | H20: 1.1 | I20: 0.96 | J20: 0.5 | K20: 0.2 | L20: 0.2 | M20: 0.9 | N20: 0.8 | O20: 0.8 | P20: 0.74 | Q20: 0.4 | R20: 0.5 | S20: 1 | T20: 0.6 | U20: 0.79 | V20: 0.39
B21: 46097 | C21: 0.6 | D21: 0.3 | E21: 0.8 | F21: 1.2 | G21: 0.4 | H21: 1 | I21: 0.85 | J21: 0.5 | K21: 0.4 | L21: 0.3 | M21: 0.8 | N21: 0.78 | O21: 0.8 | P21: 0.8 | Q21: 0.3 | R21: 0.6 | S21: 1 | T21: 0.5 | U21: 0.8 | V21: 0.15
B22: 46098 | C22: 0.9 | D22: 0.3 | E22: 0.8 | F22: 1 | G22: 0.4 | H22: 0.89 | I22: 0.91 | J22: 0.49 | K22: 0.3 | L22: 0.2 | M22: 0.8 | N22: 3.2 | O22: 0.85 | P22: 0.7 | Q22: 0.31 | R22: 0.3 | S22: 0.8 | T22: 0.5 | U22: 0.7 | V22: 0.1
B23: 46099 | C23: 0.7 | D23: 0.31 | E23: 0.8 | F23: 1.1 | G23: 0.3 | H23: 0.83 | I23: 0.8 | J23: 0.3 | K23: 0.3 | L23: 0.3 | M23: 0.9 | N23: 0.8 | O23: 0.83 | P23: 0.7 | Q23: 0.3 | R23: 0.4 | S23: 0.88 | T23: 0.5 | U23: 0.6 | V23: 0.3
B24: 46100 | C24: 0.7 | D24: 0.4 | E24: 0.8 | F24: 1.1 | G24: 0.5 | H24: 0.9 | I24: 0.8 | J24: 0.5 | K24: 0.3 | L24: 0.2 | M24: 0.9 | N24: 0.9 | O24: 0.8 | P24: 0.7 | Q24: 0.5 | R24: 0.5 | S24: 1.1 | T24: 0.5 | U24: 0.6 | V24: 0.3
B25: 46101 | C25: 0.7 | D25: 0.37 | E25: 0.82 | F25: 1 | G25: 0.4 | H25: 1.1 | I25: 0.9 | J25: 0.5 | K25: 0.3 | L25: 0.4 | M25: 0.9 | N25: 0.9 | O25: 0.8 | P25: 0.8 | Q25: 0.4 | R25: 0.4 | S25: 0.96 | T25: 0.48 | U25: 0.6 | V25: 0.3
B26: 46102 | C26: 0.64 | D26: 0.4 | E26: 0.8 | F26: 1.2 | G26: 0.39 | H26: 0.9 | I26: 1 | K26: 0.35 | L26: 0.5 | M26: 0.9 | N26: 0.9 | O26: 0.8 | P26: 0.8 | Q26: 0.36 | R26: 0.4 | S26: 1.1 | T26: 0.4 | U26: 0.7 | V26: 0.1
B27: 46103 | C27: 0.6 | D27: 0.5 | E27: 0.8 | F27: 1.2 | G27: 0.4 | H27: 0.9 | I27: 1 | J27: 0.3 | K27: 0.3 | L27: 0.4 | M27: 0.84 | N27: 0.8 | O27: 0.9 | P27: 0.9 | Q27: 0.5 | R27: 0.32 | S27: 1 | T27: 0.4 | U27: 0.6 | V27: 0.1
B28: 46104 | C28: 0.6 | D28: 0.4 | E28: 0.9 | F28: 1.09 | G28: 0.46 | H28: 0.9 | I28: 1 | J28: 0.3 | K28: 0.3 | L28: 0.3 | M28: 0.9 | N28: 0.8 | O28: 0.82 | P28: 0.9 | Q28: 0.5 | R28: 0.3 | S28: 1.01 | T28: 0.4 | U28: 0.7 | V28: 0.1
B29: 46105 | C29: 0.7 | D29: 0.38 | F29: 1.1 | G29: 0.4 | H29: 0.9 | I29: 0.9 | J29: 0.39 | K29: 0.3 | L29: 0.42 | M29: 0.9 | N29: 0.8 | O29: 0.8 | P29: 0.9 | Q29: 0.5 | R29: 0.5 | S29: 1 | T29: 0.46 | U29: 0.7 | V29: 0.2
B30: 46106 | C30: 0.7 | D30: 0.4 | E30: 0.85 | F30: 1.1 | G30: 0.35 | H30: 0.9 | I30: 0.8 | J30: 0.4 | K30: 0.3 | L30: 0.56 | M30: 1 | N30: 0.8 | O30: 0.9 | P30: 0.7 | Q30: 0.49 | R30: 0.4 | S30: 0.9 | T30: 0.5 | U30: 0.7 | V30: 0.2
B31: 46107 | C31: 0.8 | D31: 0.3 | E31: 0.7 | F31: 1.1 | G31: 0.4 | H31: 0.9 | I31: 0.9 | J31: 0.34 | K31: 0.4 | L31: 0.5 | M31: 0.7 | N31: 0.7 | O31: 1 | P31: 0.9 | Q31: 0.3 | R31: 0.4 | S31: 1.1 | T31: 0.5 | U31: 0.6 | V31: 0.2
B32: 46108 | C32: 0.9 | E32: 0.9 | F32: 1.2 | G32: 0.4 | H32: 1 | I32: 1 | J32: 0.37 | K32: 0.41 | L32: 0.4 | M32: 0.7 | N32: 0.8 | O32: 1 | P32: 0.8 | Q32: 0.2 | R32: 0.4 | S32: 1.04 | T32: 0.5 | U32: 0.7 | V32: 0.2
B33: 46109 | C33: 0.82 | D33: 0.3 | E33: 0.8 | F33: 1.1 | G33: 0.2 | H33: 1 | I33: 1 | K33: 0.46 | L33: 0.3 | M33: 0.8 | N33: 0.82 | O33: 1 | P33: 0.9 | Q33: 0.3 | R33: 0.3 | S33: 1 | T33: 0.5 | U33: 0.7 | V33: 0.27
B34: 46110 | C34: 0.64 | D34: 0.31 | E34: 0.7 | F34: 1 | G34: 0.1 | H34: 1.1 | I34: 0.8 | J34: 0.4 | K34: 0.5 | L34: 0.3 | M34: 0.9 | N34: 0.8 | O34: 0.9 | P34: 0.93 | Q34: 0.3 | R34: 0.3 | S34: 0.9 | T34: 0.5 | U34: 0.5 | V34: 0.4
B35: 46111 | C35: 0.6 | D35: 0.3 | E35: 0.8 | F35: 1.04 | G35: 0.3 | H35: 0.9 | I35: 0.84 | J35: 0.4 | K35: 0.5 | L35: 0.43 | M35: 0.8 | N35: 0.84 | O35: 1 | P35: 0.8 | Q35: 0.6 | R35: 0.2 | S35: 1 | T35: 0.5 | U35: 0.4 | V35: 0.3
B36: 46112 | C36: 0.7 | D36: 0.4 | E36: 0.7 | F36: 0.9 | G36: 0.38 | H36: 0.8 | I36: 0.84 | J36: 0.4 | K36: 0.47 | L36: 0.35 | M36: 0.87 | N36: 0.7 | O36: 0.83 | P36: 0.8 | Q36: 0.4 | R36: 0.3 | S36: 1 | T36: 0.7 | U36: 0.5 | V36: 0.3

Sheet Апрель
B4: Дата | C4: Нефть тип А | F4: Нефть тип Б | I4: Нефть тип Б | J4: Нефть тип Б | K4: Нефть тип А | S4: Нефть тип Б | U4: Узлы подготовки
C5: СИКН №301 | D5: СИКН №304 | E5: СИКН №307 | F5: СИКН №310 | G5: СИКН №312 | H5: СИКН №315 | I5: СИКН №318 | J5: ПСП Восточный | K5: СИКН №320 | L5: СИКН №322 | M5: СИКН №325 | N5: СИКН №327 | O5: СИКН №330 | P5: СИКН №333 | Q5: СИКН №336 | R5: СИКН №339 | S5: СИКН №341 | T5: СИКН №344 | U5: УПСВ-1 Лесная | V5: УПСВ-2 Озерная
B6: 46113 | C6: 0.57 | D6: 0.4 | E6: 0.7 | F6: 1 | G6: 0.4 | H6: 0.8 | I6: 0.84 | J6: 0.29 | K6: 0.5 | L6: 0.4 | M6: 0.8 | N6: 0.83 | O6: 0.9 | P6: 0.8 | Q6: 0.36 | R6: 0.3 | S6: 1.02 | T6: 0.6 | U6: 0.5 | V6: 0.2
B7: 46114 | C7: 0.4 | D7: 0.5 | E7: 0.7 | F7: 1 | G7: 0.4 | H7: 0.84 | I7: 0.7 | J7: 0.33 | K7: 0.5 | L7: 0.5 | M7: 0.82 | N7: 0.8 | O7: 0.9 | P7: 0.77 | Q7: 0.3 | R7: 0.4 | S7: 1.1 | T7: 0.6 | U7: 0.6 | V7: 0.3
B8: 46115 | C8: 0.5 | D8: 0.5 | E8: 0.7 | F8: 1 | G8: 0.5 | H8: 0.9 | I8: 0.9 | J8: 0.3 | K8: 0.5 | L8: 0.5 | M8: 0.8 | N8: 0.9 | O8: 0.9 | P8: 0.6 | Q8: 0.4 | R8: 0.38 | S8: 1.2 | T8: 0.63 | U8: 0.7 | V8: 0.28
B9: 46116 | C9: 0.66 | D9: 0.4 | E9: 0.77 | F9: 1 | G9: 0.5 | H9: 0.9 | I9: 1 | J9: 0.5 | K9: 0.5 | L9: 0.5 | M9: 0.6 | N9: 0.9 | O9: 0.94 | P9: 0.63 | Q9: 0.4 | R9: 0.4 | S9: 1.2 | T9: 0.7 | U9: 0.8 | V9: 0.3
B10: 46117 | C10: 0.6 | D10: 0.3 | E10: 0.8 | F10: 0.99 | G10: 0.3 | H10: 0.9 | I10: 0.99 | J10: 0.5 | K10: 0.6 | L10: 0.5 | M10: 0.6 | N10: 0.8 | O10: 1 | P10: 0.7 | Q10: 0.41 | R10: 0.4 | S10: 1.2 | T10: 0.6 | U10: 0.7 | V10: 0.3
B11: 46118 | C11: 0.7 | D11: 0.5 | E11: 1 | F11: 1.1 | G11: 0.45 | H11: 0.8 | I11: 0.8 | J11: 0.49 | K11: 0.5 | L11: 0.4 | M11: 0.6 | N11: 0.83 | O11: 1 | P11: 0.6 | Q11: 0.3 | R11: 0.45 | S11: 1.11 | T11: 0.6 | U11: 0.7 | V11: 0.4
B12: 46119 | C12: 0.7 | D12: 0.6 | E12: 1 | F12: 1.04 | G12: 0.6 | H12: 0.9 | I12: 1 | J12: 0.5 | K12: 0.5 | L12: 0.47 | M12: 0.6 | N12: 0.92 | O12: 1 | P12: 0.66 | Q12: 0.4 | R12: 0.5 | S12: 0.88 | T12: 0.4 | U12: 0.7 | V12: 0.4
B13: 46120 | C13: 0.7 | D13: 0.5 | E13: 0.93 | F13: 1 | G13: 0.5 | H13: 0.9 | I13: 0.9 | J13: 0.5 | K13: 0.5 | L13: 0.42 | M13: 0.7 | N13: 0.83 | O13: 0.9 | P13: 0.7 | Q13: 0.4 | R13: 0.6 | S13: 1 | T13: 0.5 | U13: 0.7 | V13: 0.28
B14: 46121 | C14: 0.9 | D14: 0.5 | E14: 0.9 | F14: 0.9 | G14: 0.5 | H14: 0.88 | J14: 0.5 | K14: 0.41 | L14: 0.47 | M14: 0.8 | N14: 0.8 | O14: 0.9 | P14: 0.7 | Q14: 0.3 | R14: 0.5 | S14: 1.1 | T14: 0.5 | U14: 0.6 | V14: 0.3
B15: 46122 | C15: 0.9 | D15: 0.5 | E15: 0.75 | F15: 1 | G15: 0.4 | H15: 0.8 | I15: 0.86 | K15: 0.5 | L15: 0.4 | M15: 0.9 | N15: 0.6 | O15: 0.8 | P15: 0.7 | Q15: 0.4 | R15: 0.4 | S15: 1.01 | U15: 0.6 | V15: 0.2
B16: 46123 | C16: 0.94 | D16: 0.5 | E16: 0.72 | F16: 1 | G16: 0.45 | H16: 0.8 | I16: 0.79 | J16: 0.5 | K16: 0.5 | L16: 0.34 | O16: 0.8 | Q16: 0.4 | R16: 0.3 | S16: 1 | T16: 0.5 | U16: 0.64 | V16: 0.3
B17: 46124 | C17: 0.8 | D17: 0.4 | E17: 0.9 | F17: 1 | G17: 0.36 | H17: 0.89 | I17: 0.8 | J17: 0.3 | K17: 0.4 | L17: 0.4 | M17: 0.8 | N17: 0.8 | O17: 0.8 | P17: 0.6 | Q17: 0.4 | R17: 0.4 | S17: 1 | T17: 0.63 | U17: 0.6 | V17: 0.26
B18: 46125 | C18: 0.75 | D18: 0.33 | E18: 0.9 | F18: 0.97 | G18: 0.4 | H18: 0.9 | I18: 0.9 | J18: 0.3 | K18: 0.4 | L18: 0.4 | M18: 0.8 | N18: 0.8 | O18: 0.8 | Q18: 0.4 | R18: 0.3 | S18: 1 | T18: 0.7 | U18: 0.5 | V18: 0.37
B19: 46126 | C19: 0.8 | D19: 0.4 | E19: 1 | F19: 0.95 | G19: 0.3 | H19: 0.9 | I19: 0.8 | J19: 0.3 | K19: 0.41 | L19: 0.3 | M19: 0.7 | N19: 0.8 | O19: 0.8 | P19: 0.7 | Q19: 0.44 | R19: 0.3 | S19: 0.98 | T19: 0.68 | U19: 0.53 | V19: 0.37
B20: 46127 | C20: 0.8 | D20: 0.38 | E20: 1 | F20: 1 | G20: 0.5 | H20: 0.9 | I20: 0.9 | J20: 0.4 | K20: 0.3 | L20: 0.4 | M20: 0.82 | N20: 0.8 | O20: 1 | P20: 0.7 | Q20: 0.5 | R20: 0.23 | S20: 1 | T20: 0.5 | U20: 0.7 | V20: 0.32
B21: 46128 | C21: 0.7 | D21: 0.4 | E21: 1 | F21: 0.9 | G21: 0.5 | H21: 0.9 | I21: 0.97 | J21: 0.3 | K21: 0.4 | L21: 0.5 | M21: 0.8 | N21: 0.7 | O21: 0.9 | P21: 0.7 | Q21: 0.4 | R21: 0.4 | S21: 1 | T21: 0.5 | V21: 0.3
B22: 46129 | C22: 0.6 | D22: 0.4 | E22: 0.9 | F22: 0.8 | G22: 0.6 | H22: 0.8 | I22: 0.9 | J22: 0.25 | K22: 0.5 | L22: 0.4 | M22: 0.7 | N22: 0.72 | O22: 0.8 | P22: 0.7 | Q22: 0.34 | T22: 0.58 | U22: 0.8 | V22: 0.3
B23: 46130 | C23: 0.7 | D23: 0.4 | E23: 1 | F23: 0.9 | G23: 0.6 | H23: 0.85 | I23: 0.9 | J23: 0.35 | K23: 0.5 | L23: 0.4 | M23: 0.72 | N23: 0.8 | O23: 0.8 | P23: 0.7 | Q23: 0.4 | R23: 0.5 | T23: 0.5 | U23: 0.8 | V23: 0.4
B24: 46131 | C24: 0.7 | D24: 0.4 | E24: 0.8 | F24: 0.9 | G24: 0.6 | H24: 0.88 | I24: 0.8 | J24: 0.5 | K24: 0.5 | L24: 0.4 | M24: 0.8 | N24: 0.7 | P24: 0.7 | Q24: 0.6 | R24: 0.5 | S24: 0.8 | T24: 0.5 | U24: 0.7 | V24: 0.2
B25: 46132 | C25: 0.6 | D25: 0.4 | E25: 0.9 | F25: 1.08 | G25: 0.5 | H25: 0.8 | I25: 0.9 | J25: 0.5 | K25: 0.4 | L25: 0.4 | M25: 0.7 | N25: 0.8 | O25: 0.82 | P25: 0.7 | Q25: 0.5 | R25: 0.51 | S25: 0.87 | T25: 0.7 | U25: 0.8 | V25: 0.3
B26: 46133 | C26: 0.6 | D26: 0.4 | E26: 0.7 | F26: 0.94 | G26: 0.3 | H26: 0.9 | I26: 0.9 | J26: 0.5 | K26: 0.4 | L26: 0.4 | M26: 0.7 | N26: 0.7 | O26: 0.8 | P26: 0.5 | Q26: 0.5 | R26: 0.4 | S26: 0.95 | T26: 0.5 | U26: 0.8 | V26: 0.2
B27: 46134 | C27: 0.57 | D27: 0.3 | E27: 0.8 | F27: 1 | G27: 0.4 | H27: 1 | I27: 1.1 | J27: 0.5 | K27: 0.4 | L27: 0.3 | M27: 0.7 | N27: 0.8 | O27: 0.9 | P27: 0.5 | Q27: 0.44 | R27: 0.4 | S27: 1 | T27: 0.58 | U27: 0.9 | V27: 0.25
B28: 46135 | C28: 0.5 | D28: 0.4 | E28: 0.9 | F28: 1.1 | G28: 0.5 | H28: 0.9 | I28: 1 | J28: 0.6 | K28: 0.4 | L28: 0.37 | M28: 0.6 | N28: 0.7 | O28: 0.9 | P28: 0.6 | Q28: 0.5 | R28: 0.38 | S28: 0.9 | T28: 0.4 | U28: 0.64 | V28: 0.3
B29: 46136 | C29: 0.55 | D29: 0.4 | E29: 0.9 | F29: 1.1 | G29: 0.4 | H29: 0.94 | I29: 1 | J29: 0.56 | K29: 0.4 | L29: 0.4 | M29: 0.6 | N29: 0.6 | O29: 0.8 | P29: 0.7 | Q29: 0.5 | R29: 0.48 | S29: 0.9 | T29: 0.4 | U29: 0.5 | V29: 0.2
B30: 46137 | C30: 0.63 | D30: 0.5 | E30: 0.7 | F30: 1.1 | G30: 0.37 | H30: 0.78 | I30: 0.9 | J30: 0.45 | K30: 0.4 | L30: 0.3 | M30: 0.6 | N30: 0.6 | O30: 0.9 | P30: 0.6 | Q30: 0.5 | R30: 0.4 | S30: 0.9 | T30: 0.4 | U30: 0.5 | V30: 0.2
B31: 46138 | C31: 0.6 | D31: 0.4 | E31: 0.7 | F31: 1.09 | G31: 0.4 | H31: 0.7 | I31: 1 | J31: 0.3 | K31: 0.34 | L31: 0.34 | M31: 0.71 | N31: 0.76 | O31: 1 | P31: 0.6 | Q31: 0.5 | R31: 0.3 | S31: 1 | T31: 0.4 | U31: 0.7 | V31: 0.2
B32: 46139 | C32: 0.63 | D32: 0.4 | E32: 0.8 | F32: 1.08 | G32: 0.4 | H32: 0.7 | I32: 1.1 | J32: 0.3 | K32: 0.26 | L32: 0.3 | M32: 0.7 | N32: 0.9 | O32: 0.9 | P32: 0.6 | Q32: 0.4 | R32: 0.5 | S32: 1.1 | T32: 0.5 | U32: 0.7 | V32: 0.3
B33: 46140 | C33: 0.6 | D33: 0.5 | E33: 0.9 | F33: 1.1 | G33: 0.4 | H33: 0.8 | I33: 1 | J33: 0.4 | K33: 0.24 | L33: 0.3 | M33: 0.8 | N33: 0.8 | O33: 0.9 | P33: 0.7 | Q33: 0.34 | R33: 0.3 | S33: 0.88 | T33: 0.6 | U33: 0.64 | V33: 0.4
B34: 46141 | C34: 0.6 | D34: 0.4 | E34: 0.8 | F34: 1.1 | G34: 0.4 | H34: 2 | I34: 0.9 | J34: 0.5 | K34: 0.3 | L34: 0.25 | M34: 0.8 | N34: 0.9 | O34: 0.9 | P34: 0.6 | Q34: 0.4 | R34: 0.31 | S34: 0.9 | T34: 0.6 | U34: 0.7 | V34: 0.3
B35: 46142 | C35: 0.7 | D35: 0.4 | E35: 0.8 | F35: 1 | G35: 0.4 | H35: 0.8 | I35: 1 | J35: 0.4 | K35: 0.41 | L35: 0.3 | M35: 0.81 | N35: 0.8 | O35: 1 | P35: 0.7 | Q35: 0.4 | R35: 0.2 | S35: 0.8 | T35: 0.51 | U35: 0.8 | V35: 0.3

Sheet Май
B4: Дата | C4: Нефть тип А | F4: Нефть тип Б | I4: Нефть тип Б | J4: Нефть тип Б | K4: Нефть тип А | S4: Нефть тип Б | U4: Узлы подготовки
C5: СИКН №301 | D5: СИКН №304 | E5: СИКН №307 | F5: СИКН №310 | G5: СИКН №312 | H5: СИКН №315 | I5: СИКН №318 | J5: ПСП Восточный | K5: СИКН №320 | L5: СИКН №322 | M5: СИКН №325 | N5: СИКН №327 | O5: СИКН №330 | P5: СИКН №333 | Q5: СИКН №336 | R5: СИКН №339 | S5: СИКН №341 | T5: СИКН №344 | U5: УПСВ-1 Лесная | V5: УПСВ-2 Озерная
B6: 46143 | C6: 0.6 | D6: 0.2 | E6: 0.8 | F6: 1.1 | G6: 0.4 | H6: 1 | K6: 0.4 | L6: 0.2 | M6: 0.9 | N6: 0.8 | O6: 1 | P6: 0.7 | Q6: 0.4 | R6: 0.32 | S6: 0.89 | T6: 0.6 | U6: 0.9 | V6: 0.27
B7: 46144 | C7: 0.6 | D7: 0.15 | E7: 0.9 | F7: 1.1 | G7: 0.6 | H7: 1 | J7: 0.6 | K7: 0.4 | L7: 0.26 | M7: 0.8 | N7: 0.7 | O7: 1 | P7: 0.7 | Q7: 0.56 | R7: 0.3 | S7: 0.8 | T7: 0.43 | U7: 0.9 | V7: 0.3
B8: 46145 | C8: 0.6 | D8: 0.2 | E8: 0.9 | F8: 0.9 | G8: 0.7 | H8: 0.82 | I8: 0.8 | J8: 0.5 | K8: 0.4 | L8: 0.2 | M8: 0.8 | N8: 0.8 | O8: 0.9 | P8: 0.6 | Q8: 0.41 | R8: 0.31 | S8: 0.8 | T8: 0.6 | U8: 0.8 | V8: 0.3
B9: 46146 | C9: 0.6 | D9: 0.3 | E9: 1 | F9: 1 | G9: 0.7 | H9: 0.8 | I9: 0.8 | J9: 0.55 | K9: 0.31 | L9: 0.2 | M9: 0.68 | N9: 0.8 | O9: 0.92 | P9: 0.57 | Q9: 0.5 | R9: 0.3 | S9: 0.9 | T9: 0.6 | U9: 0.7 | V9: 0.3
B10: 46147 | C10: 0.6 | D10: 0.28 | E10: 0.85 | F10: 1.08 | G10: 0.72 | H10: 0.9 | I10: 0.8 | J10: 0.6 | K10: 0.4 | L10: 0.2 | M10: 0.7 | N10: 0.6 | O10: 0.9 | P10: 0.6 | Q10: 0.6 | R10: 0.3 | S10: 0.9 | T10: 0.6 | U10: 0.54 | V10: 0.24
B11: 46148 | C11: 0.69 | D11: 0.4 | E11: 0.86 | F11: 1.1 | G11: 0.6 | H11: 1 | I11: 0.8 | J11: 0.6 | K11: 0.3 | L11: 0.3 | M11: 0.73 | N11: 0.8 | O11: 1 | P11: 0.68 | Q11: 0.4 | R11: 0.2 | S11: 1.03 | T11: 0.6 | U11: 0.5 | V11: 0.3
B12: 46149 | C12: 0.4 | D12: 0.3 | E12: 0.8 | F12: 1.1 | G12: 0.5 | H12: 0.9 | I12: 0.9 | J12: 0.5 | K12: 0.4 | L12: 0.4 | M12: 0.7 | N12: 0.8 | O12: 1 | P12: 0.7 | Q12: 0.29 | R12: 0.2 | S12: 1 | T12: 0.7 | U12: 0.5 | V12: 0.21
B13: 46150 | C13: 0.6 | D13: 0.36 | E13: 0.8 | F13: 1.02 | G13: 0.6 | H13: 1 | I13: 0.8 | J13: 0.38 | K13: 0.3 | L13: 0.38 | M13: 0.77 | N13: 0.8 | O13: 0.8 | P13: 0.7 | Q13: 0.38 | R13: 0.15 | S13: 1 | T13: 0.7 | U13: 0.7 | V13: 0.1
B14: 46151 | C14: 0.6 | D14: 0.4 | E14: 1 | F14: 0.9 | G14: 0.5 | H14: 1 | I14: 0.83 | J14: 0.3 | K14: 0.3 | L14: 0.27 | M14: 0.7 | N14: 0.8 | O14: 0.8 | P14: 0.7 | Q14: 0.29 | R14: 0.2 | S14: 0.9 | T14: 0.68 | U14: 0.7 | V14: 0.14
B15: 46152 | C15: 0.7 | D15: 0.3 | E15: 1 | F15: 1 | G15: 0.4 | H15: 1 | I15: 0.9 | J15: 0.4 | K15: 0.3 | L15: 0.3 | M15: 0.8 | N15: 1 | O15: 0.7 | P15: 0.8 | Q15: 0.3 | R15: 0.2 | S15: 1 | T15: 0.6 | U15: 0.6 | V15: 0.3
B16: 46153 | C16: 0.74 | D16: 0.3 | E16: 0.9 | F16: 1 | G16: 0.4 | H16: 0.9 | I16: 0.9 | J16: 0.5 | K16: 0.3 | L16: 0.5 | M16: 0.8 | N16: 1 | O16: 0.8 | P16: 0.8 | Q16: 0.5 | R16: 0.26 | S16: 1 | T16: 0.6 | U16: 0.7 | V16: 0.26
B17: 46154 | C17: 0.7 | D17: 0.2 | E17: 0.8 | F17: 0.9 | G17: 0.4 | H17: 0.9 | I17: 1 | J17: 0.4 | K17: 0.3 | L17: 0.5 | M17: 0.8 | N17: 0.82 | O17: 0.9 | P17: 0.64 | Q17: 0.4 | R17: 0.3 | S17: 1 | T17: 0.6 | U17: 0.7 | V17: 0.34
B18: 46155 | C18: 0.6 | D18: 0.4 | E18: 0.8 | F18: 1 | G18: 0.5 | H18: 0.8 | I18: 1 | J18: 0.5 | K18: 0.31 | L18: 0.55 | N18: 0.9 | O18: 0.9 | P18: 0.6 | Q18: 0.3 | R18: 0.3 | S18: 1 | T18: 0.5 | U18: 0.8 | V18: 0.3
B19: 46156 | C19: 0.6 | D19: 0.4 | E19: 0.8 | F19: 0.9 | G19: 0.5 | H19: 0.8 | I19: 1.1 | J19: 0.4 | K19: 0.4 | M19: 0.7 | N19: 0.8 | O19: 0.8 | P19: 0.8 | Q19: 0.3 | R19: 0.2 | S19: 1 | T19: 0.6 | U19: 0.7 | V19: 0.2
B20: 46157 | C20: 0.7 | D20: 0.5 | E20: 0.8 | F20: 0.9 | G20: 0.4 | H20: 0.7 | I20: 1 | J20: 0.5 | K20: 0.3 | L20: 0.47 | M20: 0.8 | N20: 0.7 | O20: 0.7 | P20: 0.7 | Q20: 0.3 | R20: 0.2 | S20: 0.9 | T20: 0.48 | U20: 0.7 | V20: 0.2
B21: 46158 | C21: 0.7 | D21: 0.4 | E21: 0.8 | F21: 0.9 | G21: 0.53 | H21: 0.7 | I21: 0.93 | J21: 0.5 | K21: 0.4 | L21: 0.2 | N21: 0.8 | O21: 0.73 | P21: 0.7 | Q21: 0.4 | S21: 1 | T21: 0.52 | U21: 0.66 | V21: 0.3
B22: 46159 | D22: 0.4 | E22: 0.7 | F22: 1 | G22: 0.5 | H22: 0.7 | I22: 1 | J22: 0.4 | K22: 0.3 | L22: 0.32 | M22: 0.7 | N22: 0.8 | O22: 0.76 | P22: 0.61 | Q22: 0.45 | R22: 0.23 | S22: 1 | T22: 0.5 | U22: 0.7 | V22: 2.7
B23: 46160 | C23: 0.7 | D23: 0.35 | E23: 0.74 | F23: 1 | G23: 0.4 | H23: 0.8 | I23: 0.9 | J23: 0.43 | K23: 0.3 | L23: 0.3 | M23: 0.7 | N23: 0.7 | O23: 0.68 | P23: 0.6 | Q23: 0.4 | R23: 0.19 | S23: 1 | T23: 0.5 | U23: 0.7 | V23: 0.3
B24: 46161 | C24: 0.6 | D24: 0.2 | E24: 0.76 | F24: 1.02 | G24: 0.37 | H24: 0.7 | I24: 0.8 | J24: 0.5 | K24: 0.41 | L24: 0.3 | M24: 0.78 | N24: 0.7 | O24: 0.8 | P24: 0.7 | Q24: 0.5 | R24: 0.26 | S24: 1 | T24: 0.4 | U24: 0.9 | V24: 0.4
B25: 46162 | C25: 0.6 | D25: 0.3 | E25: 0.9 | F25: 1 | G25: 0.3 | H25: 0.7 | I25: 0.8 | J25: 0.5 | K25: 0.3 | L25: 0.3 | M25: 0.7 | O25: 0.8 | P25: 0.8 | Q25: 0.5 | R25: 0.3 | S25: 0.9 | T25: 0.48 | U25: 0.7 | V25: 0.3
B26: 46163 | C26: 0.7 | D26: 0.3 | E26: 0.87 | F26: 1 | G26: 0.4 | H26: 0.7 | I26: 0.8 | J26: 0.5 | K26: 0.3 | L26: 0.3 | M26: 0.8 | N26: 0.78 | O26: 0.7 | Q26: 0.6 | R26: 0.4 | S26: 1 | T26: 0.6 | U26: 0.7 | V26: 0.2
B27: 46164 | C27: 0.8 | D27: 0.2 | E27: 0.8 | F27: 0.9 | G27: 0.5 | H27: 0.76 | I27: 1 | J27: 0.5 | K27: 0.4 | L27: 0.3 | M27: 0.7 | N27: 0.8 | O27: 0.8 | P27: 0.6 | Q27: 0.6 | R27: 0.3 | S27: 0.99 | T27: 0.6 | U27: 0.6 | V27: 0.3
B28: 46165 | C28: 0.85 | D28: 0.3 | E28: 0.8 | F28: 0.9 | G28: 0.5 | H28: 1 | I28: 1.1 | J28: 0.4 | K28: 0.4 | L28: 0.3 | M28: 0.8 | N28: 0.71 | O28: 0.8 | P28: 0.69 | Q28: 0.51 | R28: 0.3 | S28: 0.9 | T28: 0.6 | U28: 0.7 | V28: 0.4
B29: 46166 | C29: 0.7 | D29: 0.4 | E29: 0.8 | F29: 1 | G29: 0.4 | H29: 0.91 | I29: 1 | J29: 0.4 | K29: 0.4 | L29: 0.3 | M29: 0.7 | N29: 0.6 | O29: 0.9 | P29: 0.6 | Q29: 0.5 | R29: 0.48 | S29: 0.8 | T29: 0.5 | U29: 0.7 | V29: 0.3
B30: 46167 | C30: 0.7 | D30: 0.41 | E30: 0.9 | F30: 1 | G30: 0.4 | H30: 0.7 | I30: 1 | J30: 0.3 | K30: 0.4 | L30: 0.34 | M30: 0.6 | N30: 0.66 | O30: 1 | P30: 0.7 | Q30: 0.6 | R30: 0.4 | S30: 1 | T30: 0.6 | U30: 0.55 | V30: 0.48
B31: 46168 | C31: 0.7 | D31: 0.4 | E31: 0.9 | F31: 1 | G31: 0.4 | H31: 0.9 | I31: 1 | J31: 0.4 | K31: 0.32 | L31: 0.3 | M31: 0.73 | N31: 0.67 | O31: 0.9 | P31: 0.6 | Q31: 0.4 | R31: 0.44 | S31: 1.04 | T31: 0.5 | U31: 0.6 | V31: 0.4
B32: 46169 | C32: 0.7 | D32: 0.6 | E32: 0.79 | F32: 0.99 | G32: 0.5 | H32: 0.8 | I32: 1 | J32: 0.4 | K32: 0.5 | L32: 0.3 | M32: 0.8 | N32: 0.5 | O32: 0.9 | P32: 0.6 | Q32: 0.3 | R32: 0.4 | S32: 1.1 | T32: 0.6 | U32: 0.7 | V32: 0.3
B33: 46170 | C33: 0.8 | D33: 0.4 | E33: 0.9 | F33: 0.8 | G33: 0.56 | H33: 0.7 | I33: 0.9 | J33: 0.5 | K33: 0.4 | L33: 0.4 | M33: 0.8 | N33: 0.6 | O33: 0.94 | P33: 0.7 | Q33: 0.3 | R33: 0.3 | S33: 0.99 | T33: 0.69 | U33: 0.7 | V33: 0.3
B34: 46171 | C34: 0.8 | D34: 0.5 | E34: 0.9 | F34: 0.9 | G34: 0.56 | H34: 0.8 | I34: 0.8 | J34: 0.49 | K34: 0.4 | L34: 0.32 | M34: 0.83 | N34: 0.7 | O34: 0.88 | P34: 0.8 | Q34: 0.4 | R34: 0.26 | S34: 1 | T34: 0.6 | U34: 0.7 | V34: 0.3
B35: 46172 | C35: 0.7 | D35: 0.5 | E35: 0.9 | F35: 1 | H35: 0.8 | I35: 0.7 | J35: 0.5 | K35: 0.4 | L35: 0.3 | M35: 0.8 | N35: 0.7 | O35: 0.7 | P35: 0.8 | Q35: 0.5 | R35: 0.3 | S35: 0.9 | T35: 0.5 | U35: 0.6 | V35: 0.3
B36: 46173 | C36: 0.6 | D36: 0.45 | E36: 0.8 | F36: 1.1 | G36: 0.48 | H36: 0.8 | I36: 0.8 | J36: 0.5 | K36: 0.4 | L36: 0.36 | N36: 0.6 | O36: 0.7 | P36: 0.7 | Q36: 0.6 | R36: 0.3 | S36: 1 | T36: 0.4 | U36: 0.7 | V36: 0.26

Sheet Июнь
B4: Дата | C4: Нефть тип А | F4: Нефть тип Б | I4: Нефть тип Б | J4: Нефть тип Б | K4: Нефть тип А | S4: Нефть тип Б | U4: Узлы подготовки
C5: СИКН №301 | D5: СИКН №304 | E5: СИКН №307 | F5: СИКН №310 | G5: СИКН №312 | H5: СИКН №315 | I5: СИКН №318 | J5: ПСП Восточный | K5: СИКН №320 | L5: СИКН №322 | M5: СИКН №325 | N5: СИКН №327 | O5: СИКН №330 | P5: СИКН №333 | Q5: СИКН №336 | R5: СИКН №339 | S5: СИКН №341 | T5: СИКН №344 | U5: УПСВ-1 Лесная | V5: УПСВ-2 Озерная
B6: 46174 | C6: 0.58 | D6: 0.3 | E6: 0.8 | F6: 1.1 | G6: 0.6 | H6: 0.9 | I6: 0.68 | J6: 0.5 | K6: 0.3 | L6: 0.3 | M6: 0.7 | O6: 0.8 | P6: 0.7 | Q6: 0.6 | R6: 0.28 | S6: 0.9 | T6: 0.3 | U6: 0.8 | V6: 0.28
B7: 46175 | C7: 0.7 | E7: 0.87 | F7: 1.07 | G7: 0.6 | H7: 0.9 | I7: 0.74 | J7: 0.41 | K7: 0.5 | L7: 0.35 | M7: 0.7 | N7: 0.79 | O7: 0.9 | P7: 0.67 | Q7: 0.47 | R7: 0.4 | S7: 0.98 | T7: 0.34 | U7: 0.7 | V7: 0.32
B8: 46176 | C8: 0.7 | D8: 0.4 | E8: 0.9 | F8: 1.2 | G8: 0.7 | H8: 0.8 | I8: 0.8 | J8: 0.5 | K8: 0.61 | L8: 0.35 | M8: 0.8 | N8: 0.7 | O8: 0.87 | P8: 0.7 | Q8: 0.5 | R8: 0.4 | S8: 1 | T8: 0.5 | U8: 0.7 | V8: 0.3
B9: 46177 | C9: 0.8 | D9: 0.32 | E9: 0.8 | F9: 1.1 | G9: 0.6 | H9: 0.8 | I9: 0.8 | J9: 0.52 | K9: 0.6 | L9: 0.3 | M9: 0.82 | N9: 0.8 | O9: 0.86 | P9: 0.7 | Q9: 0.5 | R9: 0.4 | S9: 0.91 | T9: 0.5 | U9: 0.7 | V9: 0.3
B10: 46178 | C10: 0.6 | D10: 0.32 | E10: 0.9 | F10: 1.2 | G10: 0.59 | H10: 0.8 | I10: 0.86 | J10: 0.6 | K10: 0.5 | L10: 0.3 | M10: 0.7 | N10: 0.9 | O10: 0.9 | P10: 0.7 | Q10: 0.4 | R10: 0.3 | S10: 0.9 | T10: 0.5 | U10: 0.66 | V10: 0.3
B11: 46179 | C11: 0.7 | D11: 0.4 | E11: 0.87 | F11: 1 | G11: 0.5 | H11: 1 | I11: 0.8 | J11: 0.7 | K11: 0.5 | L11: 0.3 | M11: 0.7 | N11: 0.9 | O11: 0.9 | P11: 0.6 | Q11: 0.4 | R11: 0.3 | S11: 0.9 | T11: 0.6 | U11: 0.7 | V11: 0.3
B12: 46180 | C12: 0.8 | D12: 0.4 | E12: 0.8 | F12: 0.9 | G12: 0.5 | H12: 0.86 | I12: 0.8 | J12: 0.6 | K12: 0.4 | L12: 0.5 | M12: 0.8 | N12: 1 | O12: 0.9 | P12: 0.6 | Q12: 0.4 | R12: 0.2 | S12: 0.9 | T12: 0.6 | U12: 0.6 | V12: 0.3
B13: 46181 | C13: 0.7 | D13: 0.4 | E13: 0.8 | F13: 1 | H13: 0.8 | I13: 0.9 | J13: 0.5 | K13: 0.4 | L13: 0.46 | M13: 0.88 | N13: 0.8 | O13: 0.96 | P13: 0.7 | Q13: 0.3 | R13: 0.3 | S13: 1 | T13: 0.6 | U13: 0.6 | V13: 0.2
B14: 46182 | C14: 0.7 | D14: 0.5 | E14: 0.8 | F14: 1.1 | G14: 0.3 | H14: 0.9 | I14: 0.91 | J14: 0.4 | K14: 0.2 | L14: 0.38 | M14: 0.8 | N14: 0.7 | O14: 1 | P14: 0.7 | Q14: 0.4 | R14: 0.3 | S14: 1.1 | U14: 0.7 | V14: 0.2
B15: 46183 | C15: 0.8 | D15: 0.6 | E15: 0.8 | F15: 1.2 | G15: 0.4 | H15: 0.8 | I15: 1 | J15: 0.35 | K15: 0.2 | L15: 0.4 | M15: 0.6 | N15: 0.7 | O15: 1 | P15: 0.7 | Q15: 0.3 | R15: 0.33 | S15: 1 | T15: 0.4 | U15: 0.7 | V15: 0.2
B16: 46184 | C16: 0.73 | D16: 0.5 | E16: 0.71 | F16: 1.2 | G16: 0.46 | H16: 0.89 | I16: 0.9 | J16: 0.5 | K16: 0.3 | L16: 0.4 | M16: 0.7 | N16: 0.7 | O16: 0.9 | P16: 0.7 | Q16: 0.5 | R16: 0.2 | S16: 1.2 | T16: 0.5 | U16: 0.6 | V16: 0.1
B17: 46185 | C17: 0.7 | D17: 0.5 | E17: 0.8 | F17: 1.1 | G17: 0.4 | H17: 0.9 | I17: 0.8 | J17: 0.3 | K17: 0.4 | L17: 0.4 | M17: 0.8 | N17: 0.7 | O17: 1 | P17: 0.76 | Q17: 0.5 | R17: 0.3 | S17: 1.1 | T17: 0.4 | U17: 0.8 | V17: 0.2
B18: 46186 | C18: 0.6 | D18: 0.6 | E18: 0.72 | F18: 1 | G18: 0.3 | H18: 0.9 | I18: 0.8 | J18: 0.4 | K18: 0.34 | L18: 0.3 | M18: 0.6 | O18: 1 | P18: 0.7 | Q18: 0.6 | R18: 0.23 | S18: 1.2 | T18: 0.6 | U18: 0.7 | V18: 0.26
B19: 46187 | C19: 2.2 | E19: 0.8 | F19: 1.1 | G19: 0.4 | H19: 1 | I19: 0.86 | J19: 0.4 | K19: 0.4 | L19: 0.4 | M19: 0.7 | N19: 0.9 | O19: 0.9 | P19: 0.8 | Q19: 0.66 | R19: 0.3 | S19: 1.1 | T19: 0.56 | U19: 0.61 | V19: 0.3
B20: 46188 | C20: 0.6 | D20: 0.4 | E20: 0.8 | F20: 1 | G20: 0.4 | H20: 1 | I20: 0.9 | J20: 0.5 | K20: 0.5 | L20: 0.5 | M20: 0.8 | N20: 0.9 | O20: 0.8 | P20: 0.8 | Q20: 0.6 | R20: 0.36 | S20: 1 | T20: 0.5 | U20: 0.5 | V20: 0.1
B21: 46189 | C21: 0.7 | D21: 0.4 | E21: 0.9 | F21: 1 | G21: 0.5 | H21: 0.9 | I21: 0.83 | J21: 0.5 | K21: 0.4 | L21: 0.44 | M21: 0.6 | N21: 0.77 | O21: 0.7 | P21: 0.9 | Q21: 0.4 | R21: 0.2 | S21: 0.92 | U21: 0.6 | V21: 0.14
B22: 46190 | C22: 0.8 | D22: 0.5 | E22: 0.9 | F22: 1 | G22: 0.5 | H22: 0.73 | I22: 0.9 | J22: 0.5 | K22: 0.3 | L22: 0.4 | M22: 0.68 | N22: 0.8 | O22: 0.8 | P22: 0.9 | Q22: 0.5 | R22: 0.29 | S22: 0.9 | U22: 0.6 | V22: 0.2
B23: 46191 | C23: 0.8 | D23: 0.4 | E23: 0.9 | F23: 0.9 | G23: 0.49 | H23: 0.8 | I23: 0.9 | J23: 0.5 | K23: 0.3 | L23: 0.3 | M23: 0.81 | N23: 0.9 | O23: 0.8 | P23: 0.82 | Q23: 0.6 | R23: 0.3 | S23: 0.9 | T23: 0.6 | U23: 0.64 | V23: 0.2
B24: 46192 | C24: 0.7 | D24: 0.4 | E24: 0.9 | F24: 0.9 | G24: 0.4 | H24: 0.8 | I24: 1 | J24: 0.55 | K24: 0.4 | L24: 0.5 | M24: 0.7 | O24: 0.8 | P24: 0.8 | Q24: 0.5 | R24: 0.4 | S24: 0.9 | T24: 0.5 | U24: 0.6 | V24: 0.2
B25: 46193 | C25: 0.68 | D25: 0.5 | E25: 0.9 | F25: 1 | G25: 0.45 | H25: 0.8 | I25: 0.9 | J25: 0.5 | K25: 0.3 | L25: 0.3 | M25: 0.8 | N25: 0.9 | O25: 0.9 | P25: 0.8 | Q25: 0.6 | R25: 0.4 | S25: 1 | T25: 0.4 | U25: 0.63 | V25: 0.2
B26: 46194 | C26: 0.7 | D26: 0.5 | E26: 0.9 | F26: 0.9 | G26: 0.5 | I26: 0.8 | J26: 0.4 | K26: 0.2 | L26: 0.43 | M26: 0.7 | N26: 0.8 | O26: 0.8 | P26: 0.89 | Q26: 0.5 | R26: 0.4 | S26: 1 | T26: 0.6 | U26: 0.6 | V26: 0.2
B27: 46195 | C27: 0.8 | D27: 0.4 | E27: 0.9 | F27: 0.9 | G27: 0.4 | H27: 0.9 | I27: 0.9 | J27: 0.4 | K27: 0.25 | L27: 0.4 | M27: 0.73 | N27: 0.9 | O27: 0.8 | P27: 0.9 | Q27: 0.48 | R27: 0.4 | S27: 0.95 | T27: 0.5 | U27: 0.8 | V27: 0.1
B28: 46196 | C28: 0.6 | D28: 0.3 | E28: 0.7 | F28: 0.9 | G28: 0.45 | H28: 0.9 | I28: 0.9 | J28: 0.3 | K28: 0.29 | L28: 0.4 | M28: 0.7 | N28: 0.8 | O28: 0.9 | P28: 0.87 | Q28: 0.6 | R28: 0.4 | S28: 1.01 | T28: 0.5 | U28: 0.69 | V28: 0.1
B29: 46197 | C29: 0.5 | D29: 0.2 | E29: 0.7 | F29: 0.8 | G29: 0.4 | H29: 0.76 | I29: 1 | J29: 0.32 | K29: 0.3 | L29: 0.3 | M29: 0.7 | N29: 0.8 | O29: 1 | P29: 0.94 | Q29: 0.5 | R29: 0.4 | S29: 1 | T29: 0.54 | U29: 0.8 | V29: 0.2
B30: 46198 | C30: 0.7 | D30: 0.3 | E30: 0.7 | F30: 0.78 | G30: 0.45 | H30: 0.8 | I30: 0.9 | J30: 0.3 | K30: 0.3 | L30: 0.17 | M30: 0.7 | N30: 0.8 | O30: 0.9 | P30: 0.8 | Q30: 0.5 | R30: 0.29 | S30: 1 | T30: 0.5 | U30: 0.77
B31: 46199 | C31: 0.81 | D31: 0.3 | E31: 0.82 | F31: 0.9 | G31: 0.5 | H31: 0.9 | I31: 0.9 | J31: 0.3 | K31: 0.3 | L31: 0.3 | M31: 0.7 | N31: 0.7 | O31: 1 | P31: 0.7 | Q31: 0.5 | R31: 0.4 | S31: 0.9 | T31: 0.6 | U31: 0.7 | V31: 0.2
B32: 46200 | C32: 0.9 | D32: 0.3 | E32: 0.7 | F32: 0.9 | G32: 0.6 | H32: 0.8 | I32: 0.8 | J32: 0.5 | K32: 0.12 | L32: 0.3 | M32: 0.78 | N32: 0.6 | O32: 0.9 | P32: 0.7 | Q32: 0.4 | R32: 0.25 | S32: 1.09 | T32: 0.5 | U32: 0.7 | V32: 0.3
B33: 46201 | C33: 0.8 | D33: 0.3 | E33: 0.8 | F33: 0.8 | G33: 0.58 | H33: 0.84 | I33: 0.8 | J33: 0.5 | K33: 0.4 | L33: 0.4 | M33: 0.8 | N33: 0.68 | O33: 0.85 | P33: 0.8 | Q33: 0.4 | R33: 0.29 | S33: 1.1 | T33: 0.68 | U33: 0.7 | V33: 0.22
B34: 46202 | C34: 0.8 | D34: 0.3 | E34: 0.74 | F34: 0.8 | G34: 0.5 | H34: 0.8 | I34: 0.9 | J34: 0.5 | K34: 0.3 | L34: 0.3 | M34: 0.8 | N34: 0.7 | O34: 0.8 | P34: 0.7 | Q34: 0.5 | R34: 0.3 | S34: 1 | T34: 0.67 | U34: 0.6 | V34: 0.3
B35: 46203 | C35: 0.7 | E35: 0.7 | F35: 0.9 | G35: 0.6 | H35: 0.8 | I35: 0.9 | J35: 0.5 | K35: 0.3 | L35: 0.4 | M35: 0.7 | N35: 0.7 | O35: 0.9 | Q35: 0.5 | R35: 0.5 | S35: 1.2 | T35: 0.7 | U35: 0.6 | V35: 0.3

Sheet Июль
B4: Дата | C4: Нефть тип А | F4: Нефть тип Б | I4: Нефть тип Б | J4: Нефть тип Б | K4: Нефть тип А | S4: Нефть тип Б | U4: Узлы подготовки
C5: СИКН №301 | D5: СИКН №304 | E5: СИКН №307 | F5: СИКН №310 | G5: СИКН №312 | H5: СИКН №315 | I5: СИКН №318 | J5: ПСП Восточный | K5: СИКН №320 | L5: СИКН №322 | M5: СИКН №325 | N5: СИКН №327 | O5: СИКН №330 | P5: СИКН №333 | Q5: СИКН №336 | R5: СИКН №339 | S5: СИКН №341 | T5: СИКН №344 | U5: УПСВ-1 Лесная | V5: УПСВ-2 Озерная
B6: 46204 | C6: 0.8 | D6: 0.2 | E6: 0.7 | F6: 0.8 | G6: 0.6 | H6: 0.8 | I6: 0.8 | J6: 0.5 | K6: 0.4 | L6: 0.5 | M6: 0.7 | N6: 0.6 | O6: 0.96 | P6: 0.73 | Q6: 0.5 | R6: 0.47 | S6: 1.2 | T6: 0.8 | U6: 0.7 | V6: 0.3
B7: 46205 | C7: 0.7 | D7: 0.2 | E7: 0.75 | G7: 0.5 | H7: 0.9 | I7: 1 | J7: 0.3 | K7: 0.5 | L7: 0.4 | M7: 0.6 | O7: 0.9 | P7: 0.6 | Q7: 0.6 | R7: 0.4 | S7: 1.02 | T7: 0.8 | U7: 0.7 | V7: 0.3
B8: 46206 | C8: 0.66 | D8: 0.33 | E8: 0.7 | F8: 1 | G8: 0.4 | H8: 0.9 | I8: 1 | J8: 0.4 | K8: 0.5 | L8: 0.29 | M8: 0.66 | N8: 0.68 | O8: 0.9 | P8: 0.7 | Q8: 0.5 | R8: 0.3 | S8: 0.9 | T8: 0.7 | U8: 0.6 | V8: 0.28
B9: 46207 | C9: 0.7 | D9: 0.34 | E9: 0.6 | F9: 1 | G9: 1.8 | H9: 0.9 | I9: 1 | J9: 0.5 | K9: 0.3 | L9: 0.27 | M9: 0.64 | N9: 0.7 | O9: 0.99 | P9: 0.8 | Q9: 0.5 | R9: 0.2 | S9: 1 | T9: 0.7 | U9: 0.7
B10: 46208 | C10: 0.7 | D10: 0.49 | E10: 0.9 | F10: 1 | G10: 0.5 | H10: 0.9 | I10: 0.9 | J10: 0.46 | K10: 0.3 | L10: 0.4 | M10: 0.9 | N10: 0.8 | O10: 1.06 | P10: 0.7 | Q10: 0.5 | R10: 0.3 | S10: 0.97 | T10: 0.6 | U10: 0.7 | V10: 0.2
B11: 46209 | C11: 0.64 | D11: 0.3 | E11: 0.9 | F11: 1 | G11: 0.5 | H11: 0.9 | I11: 0.9 | J11: 0.4 | K11: 0.4 | L11: 0.33 | M11: 0.7 | N11: 1 | O11: 1 | P11: 0.7 | Q11: 0.56 | R11: 0.3 | S11: 0.9 | T11: 0.6 | U11: 0.7 | V11: 0.2
B12: 46210 | C12: 0.6 | D12: 0.3 | E12: 0.9 | F12: 1.1 | G12: 0.5 | H12: 1 | I12: 0.9 | J12: 0.3 | K12: 0.3 | L12: 0.23 | M12: 0.7 | N12: 0.8 | O12: 0.9 | P12: 0.8 | Q12: 0.4 | R12: 0.4 | S12: 0.95 | T12: 0.57 | U12: 0.8 | V12: 0.2
B13: 46211 | D13: 0.4 | E13: 0.9 | G13: 0.4 | H13: 0.9 | I13: 0.96 | J13: 0.41 | K13: 0.3 | L13: 0.3 | M13: 0.6 | O13: 0.8 | P13: 0.8 | Q13: 0.4 | R13: 0.3 | S13: 1 | T13: 0.6 | U13: 0.8 | V13: 0.3
B14: 46212 | C14: 0.7 | D14: 0.4 | E14: 0.77 | F14: 0.9 | G14: 0.4 | H14: 0.9 | I14: 0.9 | K14: 0.3 | M14: 0.7 | N14: 0.8 | O14: 0.9 | P14: 0.7 | Q14: 0.4 | R14: 0.31 | T14: 0.5 | U14: 0.83 | V14: 0.3
B15: 46213 | C15: 0.7 | D15: 0.4 | E15: 0.7 | F15: 0.9 | G15: 2.7 | H15: 0.9 | I15: 0.8 | J15: 0.51 | K15: 0.2 | L15: 0.39 | M15: 0.57 | N15: 0.8 | O15: 1.01 | P15: 0.7 | Q15: 0.3 | R15: 0.3 | S15: 1.1 | T15: 0.6 | U15: 0.7 | V15: 0.3
B16: 46214 | C16: 0.7 | D16: 0.32 | E16: 0.68 | F16: 1 | G16: 0.3 | H16: 1 | I16: 0.7 | J16: 0.4 | K16: 0.4 | L16: 0.4 | M16: 0.57 | N16: 0.8 | O16: 1 | P16: 0.8 | Q16: 0.2 | R16: 0.4 | S16: 1 | T16: 0.5 | U16: 0.6 | V16: 0.4
B17: 46215 | C17: 0.7 | D17: 0.4 | E17: 0.8 | F17: 1.1 | G17: 0.4 | H17: 1 | I17: 0.86 | J17: 0.4 | K17: 0.3 | L17: 0.3 | M17: 0.57 | N17: 0.8 | O17: 0.8 | P17: 0.6 | Q17: 0.4 | R17: 0.4 | S17: 0.9 | T17: 0.4 | U17: 0.7 | V17: 0.3
B18: 46216 | C18: 0.7 | D18: 0.4 | F18: 1.2 | G18: 0.5 | H18: 1.1 | I18: 0.8 | J18: 0.4 | K18: 0.3 | L18: 0.2 | M18: 0.76 | N18: 0.7 | O18: 0.9 | P18: 0.7 | Q18: 0.4 | R18: 0.37 | T18: 0.58 | U18: 0.6
B19: 46217 | C19: 0.6 | D19: 0.4 | E19: 0.7 | F19: 1.2 | G19: 0.5 | H19: 0.97 | I19: 0.84 | J19: 0.3 | K19: 0.3 | L19: 0.3 | M19: 0.7 | N19: 0.8 | O19: 0.93 | P19: 0.6 | Q19: 0.5 | R19: 0.3 | S19: 0.9 | T19: 0.6 | U19: 0.6 | V19: 0.2
B20: 46218 | C20: 0.5 | D20: 0.2 | E20: 0.7 | F20: 1.1 | G20: 0.3 | H20: 1 | I20: 0.9 | J20: 0.3 | K20: 0.4 | L20: 0.28 | M20: 0.8 | N20: 0.8 | O20: 0.93 | P20: 0.7 | Q20: 0.5 | R20: 0.3 | S20: 0.95 | T20: 0.6 | U20: 0.7 | V20: 0.2
B21: 46219 | C21: 0.6 | D21: 0.22 | E21: 0.8 | F21: 1 | G21: 0.4 | H21: 1.1 | I21: 0.8 | J21: 0.31 | K21: 0.4 | L21: 0.2 | M21: 0.7 | N21: 0.8 | O21: 0.9 | P21: 0.7 | Q21: 0.5 | R21: 0.41 | S21: 1 | T21: 0.7 | U21: 0.8 | V21: 0.2
B22: 46220 | C22: 0.6 | D22: 0.4 | E22: 0.7 | F22: 1.1 | G22: 0.43 | H22: 0.9 | I22: 0.8 | J22: 0.5 | K22: 0.35 | M22: 0.8 | N22: 0.82 | O22: 0.9 | P22: 0.8 | Q22: 0.4 | R22: 0.3 | S22: 1.1 | T22: 0.73 | U22: 0.8 | V22: 0.21
B23: 46221 | C23: 0.6 | D23: 0.3 | E23: 0.72 | F23: 0.97 | H23: 0.9 | I23: 0.8 | J23: 0.6 | K23: 0.4 | L23: 0.3 | M23: 0.79 | N23: 0.9 | O23: 1 | P23: 0.7 | Q23: 0.4 | R23: 0.3 | S23: 1 | T23: 0.6 | U23: 0.7 | V23: 0.2
B24: 46222 | C24: 0.6 | D24: 0.4 | E24: 0.7 | F24: 0.9 | G24: 0.6 | H24: 0.9 | I24: 0.88 | J24: 0.5 | K24: 0.3 | L24: 0.3 | M24: 0.7 | N24: 0.8 | O24: 1.01 | P24: 0.6 | Q24: 0.4 | R24: 0.4 | S24: 1 | T24: 0.5 | U24: 0.7 | V24: 0.35
B25: 46223 | C25: 0.6 | D25: 0.48 | E25: 0.7 | F25: 0.9 | G25: 0.4 | H25: 0.9 | I25: 0.8 | J25: 0.3 | K25: 0.4 | L25: 0.4 | M25: 0.6 | N25: 0.7 | O25: 1 | P25: 0.7 | Q25: 0.4 | R25: 0.3 | S25: 1.1 | T25: 0.6 | U25: 0.7 | V25: 0.4
B26: 46224 | C26: 0.7 | D26: 0.3 | E26: 0.8 | F26: 1 | G26: 0.44 | H26: 0.9 | I26: 0.8 | J26: 0.4 | K26: 0.19 | L26: 0.4 | M26: 0.6 | N26: 0.9 | O26: 1 | P26: 0.73 | Q26: 0.4 | R26: 0.3 | S26: 0.9 | U26: 0.8 | V26: 0.23
B27: 46225 | C27: 0.7 | D27: 0.5 | E27: 0.8 | F27: 1 | G27: 0.3 | H27: 0.9 | I27: 0.8 | J27: 0.2 | K27: 0.19 | L27: 0.2 | M27: 0.6 | N27: 0.9 | O27: 0.9 | P27: 0.8 | Q27: 0.4 | R27: 0.4 | S27: 0.8 | T27: 0.46 | U27: 0.7 | V27: 0.2
B28: 46226 | C28: 0.7 | D28: 0.5 | E28: 0.9 | F28: 0.9 | G28: 0.4 | H28: 0.8 | I28: 0.76 | J28: 0.38 | K28: 0.3 | L28: 0.3 | M28: 0.76 | N28: 0.9 | O28: 0.97 | P28: 0.8 | Q28: 0.4 | R28: 0.3 | S28: 0.9 | T28: 0.5 | U28: 0.78 | V28: 0.3
B29: 46227 | C29: 0.6 | D29: 0.5 | E29: 0.93 | F29: 0.9 | G29: 0.3 | H29: 0.8 | I29: 0.8 | J29: 0.3 | K29: 0.3 | L29: 0.4 | M29: 0.63 | N29: 0.97 | O29: 1 | P29: 0.8 | Q29: 0.4 | R29: 0.25 | S29: 0.9 | T29: 0.6 | U29: 0.8 | V29: 0.4
B30: 46228 | C30: 0.8 | D30: 0.5 | E30: 0.9 | F30: 0.9 | G30: 0.4 | H30: 1 | I30: 0.8 | J30: 0.3 | L30: 0.4 | M30: 0.6 | N30: 0.9 | O30: 1 | P30: 0.84 | Q30: 0.54 | R30: 0.2 | S30: 0.9 | T30: 0.5 | U30: 0.8 | V30: 0.3
B31: 46229 | C31: 0.74 | D31: 0.44 | E31: 0.7 | F31: 1 | G31: 0.3 | H31: 0.9 | I31: 1 | J31: 0.3 | K31: 0.2 | L31: 0.4 | M31: 0.6 | N31: 0.78 | O31: 0.98 | P31: 0.8 | Q31: 0.4 | R31: 0.2 | S31: 0.9 | T31: 0.5 | U31: 0.73 | V31: 0.2
B32: 46230 | C32: 0.8 | D32: 0.5 | E32: 0.8 | F32: 1.1 | G32: 0.4 | H32: 0.9 | I32: 1 | J32: 0.3 | K32: 0.1 | L32: 0.4 | M32: 0.7 | N32: 0.68 | O32: 0.87 | P32: 0.6 | Q32: 0.4 | R32: 0.4 | S32: 0.91 | T32: 0.5 | U32: 0.8 | V32: 0.38
B33: 46231 | C33: 0.59 | D33: 0.45 | E33: 0.8 | F33: 0.95 | G33: 0.5 | H33: 0.8 | I33: 0.9 | J33: 0.2 | K33: 0.3 | L33: 0.3 | M33: 0.7 | N33: 0.7 | O33: 0.8 | P33: 0.7 | Q33: 0.5 | R33: 0.5 | S33: 0.8 | T33: 0.47 | U33: 0.8 | V33: 0.3
B34: 46232 | C34: 0.6 | D34: 0.5 | E34: 0.7 | F34: 0.94 | G34: 0.5 | H34: 0.72 | I34: 0.84 | J34: 0.3 | K34: 0.3 | L34: 0.4 | M34: 0.76 | N34: 0.8 | O34: 0.9 | P34: 0.65 | Q34: 0.5 | R34: 0.4 | S34: 0.9 | T34: 0.5 | U34: 0.7
B35: 46233 | C35: 0.6 | E35: 0.8 | F35: 1.1 | G35: 0.5 | H35: 0.7 | I35: 0.8 | J35: 0.35 | K35: 0.3 | L35: 0.4 | M35: 0.8 | N35: 0.6 | O35: 0.9 | P35: 0.7 | Q35: 0.51 | R35: 0.35 | S35: 0.8 | T35: 0.5 | U35: 0.7 | V35: 0.25
B36: 46234 | C36: 0.6 | D36: 0.6 | E36: 0.9 | F36: 0.9 | G36: 0.5 | H36: 0.7 | I36: 0.9 | J36: 0.4 | K36: 0.3 | L36: 0.5 | M36: 0.7 | N36: 0.75 | O36: 1 | P36: 0.7 | Q36: 0.6 | R36: 0.3 | S36: 0.74 | T36: 0.5 | U36: 0.6 | V36: 0.2

Sheet Август
B4: Дата | C4: Нефть тип А | F4: Нефть тип Б | I4: Нефть тип Б | J4: Нефть тип Б | K4: Нефть тип А | S4: Нефть тип Б | U4: Узлы подготовки
C5: СИКН №301 | D5: СИКН №304 | E5: СИКН №307 | F5: СИКН №310 | G5: СИКН №312 | H5: СИКН №315 | I5: СИКН №318 | J5: ПСП Восточный | K5: СИКН №320 | L5: СИКН №322 | M5: СИКН №325 | N5: СИКН №327 | O5: СИКН №330 | P5: СИКН №333 | Q5: СИКН №336 | R5: СИКН №339 | S5: СИКН №341 | T5: СИКН №344 | U5: УПСВ-1 Лесная | V5: УПСВ-2 Озерная
B6: 46235 | C6: 0.64 | D6: 0.6 | E6: 0.8 | F6: 0.8 | G6: 0.4 | H6: 0.7 | I6: 1 | J6: 0.5 | K6: 0.4 | L6: 0.4 | M6: 0.6 | N6: 0.7 | O6: 0.9 | P6: 0.8 | Q6: 0.4 | R6: 0.4 | S6: 0.9 | T6: 0.5 | U6: 0.61 | V6: 0.25
B7: 46236 | C7: 0.8 | D7: 0.49 | E7: 0.7 | F7: 1 | G7: 0.4 | H7: 0.69 | I7: 1 | J7: 0.41 | L7: 0.5 | M7: 0.65 | N7: 0.8 | O7: 0.9 | P7: 0.8 | Q7: 0.4 | R7: 0.5 | S7: 1 | T7: 0.6 | U7: 0.7 | V7: 0.3
B8: 46237 | C8: 0.7 | D8: 0.4 | E8: 0.7 | F8: 1.1 | G8: 0.5 | H8: 0.9 | I8: 1 | J8: 0.6 | K8: 0.4 | L8: 0.5 | M8: 0.7 | N8: 0.89 | O8: 0.85 | P8: 0.8 | Q8: 0.3 | R8: 0.4 | S8: 1.1 | T8: 0.5 | U8: 0.7 | V8: 0.2
B9: 46238 | C9: 0.67 | D9: 0.5 | E9: 0.75 | F9: 1 | G9: 0.55 | H9: 1 | I9: 0.9 | J9: 0.44 | K9: 0.34 | L9: 0.5 | M9: 0.7 | N9: 0.73 | O9: 0.9 | P9: 0.89 | Q9: 0.31 | R9: 0.25 | S9: 1.1 | T9: 0.6 | U9: 0.7 | V9: 0.2
B10: 46239 | C10: 0.76 | D10: 0.5 | E10: 0.8 | F10: 1 | G10: 0.6 | H10: 0.9 | I10: 0.84 | J10: 0.4 | K10: 0.4 | L10: 0.28 | M10: 0.6 | N10: 0.79 | O10: 1 | P10: 0.9 | Q10: 0.4 | R10: 0.1 | S10: 1.08 | T10: 0.58 | U10: 0.6 | V10: 0.2
B11: 46240 | C11: 0.7 | D11: 0.4 | E11: 0.8 | F11: 0.9 | G11: 0.5 | H11: 1 | I11: 0.8 | J11: 0.43 | K11: 0.3 | L11: 0.4 | M11: 0.7 | N11: 0.8 | O11: 1.1 | P11: 0.8 | Q11: 0.22 | R11: 0.14 | S11: 1.1 | T11: 0.7 | U11: 0.7 | V11: 0.2
B12: 46241 | C12: 0.7 | D12: 0.57 | E12: 0.8 | F12: 1.02 | G12: 0.5 | H12: 1 | I12: 2.5 | J12: 0.4 | K12: 0.3 | L12: 0.5 | M12: 0.8 | N12: 0.7 | O12: 1 | P12: 0.7 | Q12: 0.3 | R12: 0.3 | S12: 0.9 | T12: 0.7 | U12: 0.7 | V12: 0.2
B13: 46242 | C13: 0.6 | D13: 0.5 | E13: 0.75 | F13: 1 | G13: 0.5 | H13: 1 | I13: 0.7 | K13: 0.4 | L13: 0.4 | M13: 0.7 | N13: 0.9 | O13: 0.9 | P13: 0.7 | Q13: 0.3 | R13: 0.3 | S13: 1 | T13: 0.6 | U13: 0.7 | V13: 0.16
B14: 46243 | C14: 0.8 | D14: 0.3 | E14: 0.7 | F14: 0.97 | G14: 0.57 | H14: 1 | I14: 0.8 | J14: 0.5 | K14: 0.4 | L14: 0.5 | M14: 0.7 | N14: 0.9 | O14: 0.9 | Q14: 0.4 | R14: 0.2 | S14: 0.9 | T14: 0.7 | U14: 0.63 | V14: 0.2
B15: 46244 | C15: 0.7 | D15: 0.3 | E15: 1 | F15: 1.2 | G15: 0.4 | H15: 0.8 | I15: 0.8 | J15: 0.6 | K15: 0.4 | L15: 0.4 | M15: 0.7 | N15: 0.9 | O15: 0.9 | P15: 0.8 | Q15: 0.44 | R15: 0.3 | S15: 1 | T15: 0.58 | U15: 0.7 | V15: 0.3
B16: 46245 | C16: 0.6 | D16: 0.4 | E16: 0.95 | F16: 1 | G16: 0.4 | H16: 0.8 | I16: 0.8 | J16: 0.5 | K16: 0.4 | L16: 0.3 | M16: 0.7 | N16: 0.9 | O16: 0.84 | P16: 0.7 | Q16: 0.31 | R16: 0.3 | S16: 1 | T16: 0.6 | U16: 0.7 | V16: 0.3
B17: 46246 | C17: 0.6 | D17: 0.4 | E17: 0.8 | F17: 0.91 | G17: 0.5 | H17: 0.7 | I17: 0.8 | J17: 0.6 | K17: 0.4 | L17: 0.3 | M17: 0.7 | N17: 0.9 | O17: 1 | P17: 0.7 | Q17: 0.3 | R17: 0.4 | S17: 1.1 | T17: 0.5 | U17: 0.8 | V17: 0.26
B18: 46247 | C18: 0.5 | D18: 0.4 | E18: 0.8 | F18: 0.97 | G18: 0.5 | H18: 0.72 | I18: 0.9 | J18: 0.6 | K18: 0.6 | L18: 0.36 | M18: 0.7 | N18: 1 | O18: 0.9 | P18: 0.7 | Q18: 0.3 | R18: 0.3 | S18: 1.2 | T18: 0.5 | U18: 0.9 | V18: 0.4
B19: 46248 | C19: 0.5 | D19: 0.31 | E19: 0.7 | F19: 1 | G19: 0.5 | H19: 0.8 | I19: 0.9 | J19: 0.5 | K19: 0.5 | L19: 0.3 | M19: 0.7 | N19: 0.9 | O19: 0.9 | P19: 0.6 | Q19: 0.4 | R19: 0.4 | S19: 1.2 | T19: 0.6 | U19: 0.87 | V19: 0.29
B20: 46249 | C20: 0.6 | D20: 0.37 | E20: 0.9 | F20: 1 | G20: 0.4 | H20: 0.8 | I20: 1 | J20: 0.5 | K20: 0.35 | L20: 0.3 | M20: 0.8 | N20: 0.7 | O20: 0.8 | P20: 0.62 | R20: 0.4 | S20: 1.06 | T20: 0.5 | U20: 0.79 | V20: 0.3
B21: 46250 | C21: 0.7 | D21: 0.3 | E21: 0.77 | F21: 1 | G21: 0.41 | H21: 0.8 | I21: 0.8 | J21: 0.3 | K21: 0.4 | L21: 0.3 | M21: 0.85 | N21: 0.66 | O21: 0.9 | P21: 0.69 | Q21: 0.4 | R21: 0.3 | S21: 1.1 | T21: 0.6 | U21: 0.69 | V21: 0.3
B22: 46251 | C22: 0.6 | D22: 0.5 | E22: 0.9 | F22: 0.9 | G22: 0.3 | H22: 0.7 | I22: 0.8 | J22: 0.4 | K22: 0.4 | L22: 0.3 | M22: 0.9 | N22: 0.8 | O22: 1 | P22: 0.7 | Q22: 0.3 | R22: 0.2 | S22: 0.8 | T22: 0.6 | U22: 0.7 | V22: 0.33
B23: 46252 | C23: 0.6 | D23: 0.5 | E23: 0.84 | F23: 1 | G23: 0.3 | H23: 0.7 | I23: 0.82 | J23: 0.5 | K23: 0.4 | L23: 0.4 | M23: 0.91 | N23: 0.9 | O23: 1 | P23: 0.6 | Q23: 0.3 | R23: 0.2 | S23: 0.89 | T23: 0.4 | U23: 0.56 | V23: 0.25
B24: 46253 | C24: 0.6 | D24: 0.53 | E24: 0.87 | F24: 0.9 | G24: 0.5 | H24: 0.6 | I24: 0.8 | J24: 0.44 | K24: 0.41 | L24: 0.4 | M24: 0.87 | N24: 0.93 | O24: 0.93 | P24: 0.6 | Q24: 0.3 | R24: 0.3 | S24: 1 | T24: 0.5 | U24: 0.66 | V24: 0.3
B25: 46254 | C25: 0.7 | D25: 0.4 | E25: 0.9 | F25: 0.8 | G25: 0.5 | H25: 0.7 | I25: 0.78 | J25: 0.54 | K25: 0.4 | L25: 0.4 | M25: 0.8 | N25: 0.9 | O25: 0.9 | P25: 0.7 | Q25: 0.3 | R25: 0.31 | S25: 1 | T25: 0.5 | U25: 0.6 | V25: 0.3
B26: 46255 | C26: 0.7 | D26: 0.58 | E26: 0.8 | F26: 0.9 | G26: 0.5 | H26: 0.78 | I26: 0.8 | J26: 0.58 | K26: 0.5 | L26: 0.4 | M26: 0.8 | N26: 0.7 | O26: 0.9 | P26: 0.7 | Q26: 0.3 | R26: 0.2 | S26: 1 | T26: 0.51 | U26: 0.6 | V26: 0.3
B27: 46256 | C27: 0.7 | D27: 0.52 | E27: 0.8 | F27: 0.9 | G27: 0.5 | H27: 0.8 | I27: 0.8 | J27: 0.55 | K27: 0.5 | L27: 0.5 | M27: 0.6 | N27: 0.6 | O27: 1 | P27: 0.7 | Q27: 0.43 | S27: 1.1 | T27: 0.4 | U27: 0.6 | V27: 0.4
B28: 46257 | C28: 0.8 | D28: 0.5 | E28: 0.8 | F28: 0.95 | G28: 0.3 | H28: 0.88 | J28: 0.5 | K28: 0.37 | L28: 0.4 | M28: 0.7 | N28: 0.7 | O28: 0.9 | P28: 0.8 | Q28: 0.46 | R28: 0.2 | S28: 1.1 | T28: 0.6 | U28: 0.6 | V28: 0.4
B29: 46258 | C29: 0.8 | D29: 0.51 | E29: 0.8 | F29: 1 | G29: 0.3 | H29: 0.8 | I29: 0.9 | J29: 0.6 | K29: 0.5 | L29: 0.42 | M29: 0.69 | N29: 0.5 | O29: 1 | P29: 0.69 | Q29: 0.4 | R29: 0.3 | S29: 1 | T29: 0.53 | U29: 0.7 | V29: 0.3
B30: 46259 | C30: 0.7 | D30: 0.6 | E30: 0.9 | F30: 0.9 | G30: 0.3 | H30: 0.8 | I30: 0.8 | J30: 0.6 | K30: 0.5 | L30: 0.4 | M30: 0.8 | N30: 0.7 | O30: 0.9 | P30: 0.74 | Q30: 0.5 | R30: 0.3 | S30: 1.12 | T30: 0.4 | U30: 0.7 | V30: 0.3
B31: 46260 | C31: 0.8 | D31: 0.5 | E31: 0.9 | G31: 0.4 | H31: 0.8 | I31: 0.8 | J31: 0.6 | K31: 0.5 | L31: 0.2 | M31: 0.6 | N31: 0.79 | O31: 0.8 | P31: 0.8 | Q31: 0.3 | R31: 0.4 | S31: 1 | T31: 0.39 | U31: 0.8 | V31: 0.4
B32: 46261 | C32: 0.7 | E32: 0.95 | F32: 1.05 | G32: 0.5 | H32: 0.8 | I32: 0.8 | J32: 0.6 | K32: 0.35 | L32: 0.4 | M32: 0.7 | N32: 0.9 | O32: 0.8 | P32: 0.7 | Q32: 0.4 | R32: 0.4 | S32: 1 | T32: 0.5 | U32: 0.7 | V32: 0.3
B33: 46262 | C33: 0.6 | D33: 0.5 | E33: 1 | F33: 1.1 | G33: 0.5 | H33: 0.9 | I33: 0.9 | J33: 0.3 | K33: 0.3 | L33: 0.42 | M33: 0.8 | N33: 1 | O33: 0.91 | P33: 0.7 | Q33: 0.42 | R33: 0.36 | S33: 1 | T33: 0.6 | U33: 0.7 | V33: 0.25
B34: 46263 | C34: 0.7 | D34: 0.5 | E34: 0.9 | F34: 1.1 | G34: 0.5 | H34: 0.9 | I34: 0.9 | J34: 0.3 | K34: 0.17 | L34: 0.4 | M34: 0.7 | N34: 1 | O34: 0.86 | P34: 0.7 | Q34: 0.4 | R34: 0.5 | S34: 1 | T34: 0.5 | U34: 0.6 | V34: 0.2
B35: 46264 | C35: 0.7 | D35: 0.4 | E35: 0.8 | F35: 0.97 | G35: 0.6 | H35: 1 | I35: 0.8 | J35: 0.47 | K35: 0.2 | L35: 0.5 | M35: 0.71 | N35: 1.06 | O35: 0.8 | P35: 0.7 | Q35: 0.5 | R35: 0.6 | S35: 1.1 | T35: 0.66 | U35: 0.6 | V35: 0.3
B36: 46265 | C36: 0.7 | D36: 0.5 | E36: 0.83 | F36: 1.1 | G36: 0.6 | H36: 0.78 | I36: 0.8 | J36: 0.5 | K36: 0.19 | L36: 0.5 | M36: 0.7 | N36: 1 | O36: 0.9 | P36: 0.7 | Q36: 0.5 | R36: 0.7 | S36: 1 | T36: 0.7 | U36: 0.7 | V36: 0.3

Sheet Сентябрь
B4: Дата | C4: Нефть тип А | F4: Нефть тип Б | I4: Нефть тип Б | J4: Нефть тип Б | K4: Нефть тип А | S4: Нефть тип Б | U4: Узлы подготовки
C5: СИКН №301 | D5: СИКН №304 | E5: СИКН №307 | F5: СИКН №310 | G5: СИКН №312 | H5: СИКН №315 | I5: СИКН №318 | J5: ПСП Восточный | K5: СИКН №320 | L5: СИКН №322 | M5: СИКН №325 | N5: СИКН №327 | O5: СИКН №330 | P5: СИКН №333 | Q5: СИКН №336 | R5: СИКН №339 | S5: СИКН №341 | T5: СИКН №344 | U5: УПСВ-1 Лесная | V5: УПСВ-2 Озерная
B6: 46266 | C6: 0.7 | D6: 0.5 | E6: 0.8 | F6: 1.1 | G6: 0.6 | H6: 0.7 | I6: 0.7 | J6: 0.43 | K6: 0.3 | L6: 0.5 | M6: 0.8 | N6: 0.9 | O6: 0.8 | P6: 0.8 | Q6: 0.5 | R6: 0.6 | S6: 1.1 | T6: 0.7 | U6: 0.7 | V6: 0.31
